[2023-08-25 09:51:19,854: INFO: main: >>>>>> stage Data Ingestion stage started <<<<<<]
[2023-08-25 09:51:19,856: INFO: common: yaml file: config\config.yaml loaded successfully]
[2023-08-25 09:51:19,857: INFO: common: yaml file: params.yaml loaded successfully]
[2023-08-25 09:51:19,857: INFO: common: created directory at: artifacts]
[2023-08-25 09:51:19,857: INFO: common: created directory at: artifacts/data_ingestion]
[2023-08-25 09:51:23,391: INFO: data_ingestion: artifacts/data_ingestion/data.zip download! with following info: 
Connection: close
Content-Length: 7903594
Cache-Control: max-age=300
Content-Security-Policy: default-src 'none'; style-src 'unsafe-inline'; sandbox
Content-Type: application/zip
ETag: "dbc016a060da18070593b83afff580c9b300f0b6ea4147a7988433e04df246ca"
Strict-Transport-Security: max-age=31536000
X-Content-Type-Options: nosniff
X-Frame-Options: deny
X-XSS-Protection: 1; mode=block
X-GitHub-Request-Id: 9700:387705:47FB7:7047F:64E82C1A
Accept-Ranges: bytes
Date: Fri, 25 Aug 2023 04:20:47 GMT
Via: 1.1 varnish
X-Served-By: cache-del21749-DEL
X-Cache: MISS
X-Cache-Hits: 0
X-Timer: S1692937245.734427,VS0,VE2411
Vary: Authorization,Accept-Encoding,Origin
Access-Control-Allow-Origin: *
Cross-Origin-Resource-Policy: cross-origin
X-Fastly-Request-ID: e3a132156e7c2946b09636115ea5a5ad5fbeb78b
Expires: Fri, 25 Aug 2023 04:25:47 GMT
Source-Age: 2

]
[2023-08-25 09:51:23,470: INFO: main: >>>>>> stage Data Ingestion stage completed <<<<<<

x==========x]
[2023-08-25 09:51:23,471: INFO: main: >>>>>> stage Data Validation stage started <<<<<<]
[2023-08-25 09:51:23,472: INFO: common: yaml file: config\config.yaml loaded successfully]
[2023-08-25 09:51:23,473: INFO: common: yaml file: params.yaml loaded successfully]
[2023-08-25 09:51:23,473: INFO: common: created directory at: artifacts]
[2023-08-25 09:51:23,473: INFO: common: created directory at: artifacts/data_validation]
[2023-08-25 09:51:23,474: INFO: main: >>>>>> stage Data Validation stage completed <<<<<<

x==========x]
[2023-08-25 09:51:23,474: INFO: main: >>>>>> stage Data Transformation stage started <<<<<<]
[2023-08-25 09:51:23,476: INFO: common: yaml file: config\config.yaml loaded successfully]
[2023-08-25 09:51:23,477: INFO: common: yaml file: params.yaml loaded successfully]
[2023-08-25 09:51:23,477: INFO: common: created directory at: artifacts]
[2023-08-25 09:51:23,477: INFO: common: created directory at: artifacts/data_transformation]
[2023-08-25 09:51:29,937: INFO: main: >>>>>> stage Data Transformation stage completed <<<<<<

x==========x]
[2023-08-25 09:51:29,937: INFO: main: *******************]
[2023-08-25 09:51:29,937: INFO: main: >>>>>> stage Model Trainer stage started <<<<<<]
[2023-08-25 09:51:29,939: INFO: common: yaml file: config\config.yaml loaded successfully]
[2023-08-25 09:51:29,940: INFO: common: yaml file: params.yaml loaded successfully]
[2023-08-25 09:51:29,940: INFO: common: created directory at: artifacts]
[2023-08-25 09:51:29,940: INFO: common: created directory at: artifacts/model_trainer]
[2023-08-25 09:54:48,591: ERROR: main: Using the `Trainer` with `PyTorch` requires `accelerate>=0.20.1`: Please run `pip install transformers[torch]` or `pip install accelerate -U`]
Traceback (most recent call last):
  File "c:\Users\shiva\OneDrive\Desktop\Text-Summarization-NLP-Project-main\main.py", line 51, in <module>
    model_trainer.main()
  File "c:\users\shiva\onedrive\desktop\text-summarization-nlp-project-main\src\textSummarizer\pipeline\stage_04_model_trainer.py", line 14, in main
    model_trainer_config.train()
  File "c:\users\shiva\onedrive\desktop\text-summarization-nlp-project-main\src\textSummarizer\conponents\model_trainer.py", line 34, in train
    trainer_args = TrainingArguments(
  File "<string>", line 113, in __init__
  File "C:\Users\shiva\.conda\envs\venv\lib\site-packages\transformers\training_args.py", line 1400, in __post_init__
    and (self.device.type != "cuda")
  File "C:\Users\shiva\.conda\envs\venv\lib\site-packages\transformers\training_args.py", line 1857, in device
    return self._setup_devices
  File "C:\Users\shiva\.conda\envs\venv\lib\site-packages\transformers\utils\generic.py", line 54, in __get__
    cached = self.fget(obj)
  File "C:\Users\shiva\.conda\envs\venv\lib\site-packages\transformers\training_args.py", line 1772, in _setup_devices
    raise ImportError(
ImportError: Using the `Trainer` with `PyTorch` requires `accelerate>=0.20.1`: Please run `pip install transformers[torch]` or `pip install accelerate -U`
[2023-08-25 09:55:21,653: INFO: main: >>>>>> stage Data Ingestion stage started <<<<<<]
[2023-08-25 09:55:21,654: INFO: common: yaml file: config\config.yaml loaded successfully]
[2023-08-25 09:55:21,655: INFO: common: yaml file: params.yaml loaded successfully]
[2023-08-25 09:55:21,655: INFO: common: created directory at: artifacts]
[2023-08-25 09:55:21,655: INFO: common: created directory at: artifacts/data_ingestion]
[2023-08-25 09:55:21,656: INFO: data_ingestion: File already exists of size: ~ 7718 KB]
[2023-08-25 09:55:21,727: INFO: main: >>>>>> stage Data Ingestion stage completed <<<<<<

x==========x]
[2023-08-25 09:55:21,727: INFO: main: >>>>>> stage Data Validation stage started <<<<<<]
[2023-08-25 09:55:21,730: INFO: common: yaml file: config\config.yaml loaded successfully]
[2023-08-25 09:55:21,731: INFO: common: yaml file: params.yaml loaded successfully]
[2023-08-25 09:55:21,731: INFO: common: created directory at: artifacts]
[2023-08-25 09:55:21,731: INFO: common: created directory at: artifacts/data_validation]
[2023-08-25 09:55:21,732: INFO: main: >>>>>> stage Data Validation stage completed <<<<<<

x==========x]
[2023-08-25 09:55:21,732: INFO: main: >>>>>> stage Data Transformation stage started <<<<<<]
[2023-08-25 09:55:21,734: INFO: common: yaml file: config\config.yaml loaded successfully]
[2023-08-25 09:55:21,735: INFO: common: yaml file: params.yaml loaded successfully]
[2023-08-25 09:55:21,735: INFO: common: created directory at: artifacts]
[2023-08-25 09:55:21,735: INFO: common: created directory at: artifacts/data_transformation]
[2023-08-25 09:55:22,797: INFO: main: >>>>>> stage Data Transformation stage completed <<<<<<

x==========x]
[2023-08-25 09:55:22,797: INFO: main: *******************]
[2023-08-25 09:55:22,798: INFO: main: >>>>>> stage Model Trainer stage started <<<<<<]
[2023-08-25 09:55:22,799: INFO: common: yaml file: config\config.yaml loaded successfully]
[2023-08-25 09:55:22,800: INFO: common: yaml file: params.yaml loaded successfully]
[2023-08-25 09:55:22,800: INFO: common: created directory at: artifacts]
[2023-08-25 09:55:22,801: INFO: common: created directory at: artifacts/model_trainer]
[2023-08-25 14:41:56,563: INFO: main: >>>>>> stage Model Trainer stage completed <<<<<<

x==========x]
[2023-08-25 14:41:56,563: INFO: main: *******************]
[2023-08-25 14:41:56,564: INFO: main: >>>>>> stage Model Evaluation stage started <<<<<<]
[2023-08-25 14:41:56,570: INFO: common: yaml file: config\config.yaml loaded successfully]
[2023-08-25 14:41:56,576: INFO: common: yaml file: params.yaml loaded successfully]
[2023-08-25 14:41:56,576: INFO: common: created directory at: artifacts]
[2023-08-25 14:41:56,576: INFO: common: created directory at: artifacts/model_evaluation]
[2023-08-25 14:42:49,227: INFO: rouge_scorer: Using default tokenizer.]
[2023-08-25 14:42:49,306: INFO: main: >>>>>> stage Model Evaluation stage completed <<<<<<

x==========x]
[2023-08-25 14:43:04,947: INFO: server: Started server process [21124]]
[2023-08-25 14:43:04,947: INFO: on: Waiting for application startup.]
[2023-08-25 14:43:04,948: INFO: on: Application startup complete.]
[2023-08-25 14:43:04,948: INFO: server: Uvicorn running on http://0.0.0.0:8080 (Press CTRL+C to quit)]
[2023-08-25 14:47:11,870: INFO: server: Started server process [15592]]
[2023-08-25 14:47:11,870: INFO: on: Waiting for application startup.]
[2023-08-25 14:47:11,870: INFO: on: Application startup complete.]
[2023-08-25 14:47:11,871: INFO: server: Uvicorn running on http://0.0.0.0:8080 (Press CTRL+C to quit)]
[2023-08-25 14:49:27,340: INFO: common: yaml file: config\config.yaml loaded successfully]
[2023-08-25 14:49:27,343: INFO: common: yaml file: params.yaml loaded successfully]
[2023-08-25 14:49:27,344: INFO: common: created directory at: artifacts]
[2023-08-25 14:49:27,345: INFO: common: created directory at: artifacts/model_evaluation]
[2023-09-07 10:32:31,361: INFO: main: >>>>>> stage Data Ingestion stage started <<<<<<]
[2023-09-07 10:32:31,376: INFO: common: yaml file: config\config.yaml loaded successfully]
[2023-09-07 10:32:31,376: INFO: common: yaml file: params.yaml loaded successfully]
[2023-09-07 10:32:31,376: INFO: common: created directory at: artifacts]
[2023-09-07 10:32:31,376: INFO: common: created directory at: artifacts/data_ingestion]
[2023-09-07 10:32:31,376: ERROR: main: <urlopen error unknown url type: https>]
Traceback (most recent call last):
  File "c:\Users\shiva\OneDrive\Desktop\shivam\Text_Summarization\main.py", line 13, in <module>
    data_ingestion.main()
  File "c:\users\shiva\onedrive\desktop\shivam\text_summarization\src\textSummarizer\pipeline\stage_01_data_ingestion.py", line 14, in main
    data_ingestion.download_file()
  File "c:\users\shiva\onedrive\desktop\shivam\text_summarization\src\textSummarizer\conponents\data_ingestion.py", line 18, in download_file
    filename, headers = request.urlretrieve(
  File "C:\Users\shiva\.conda\envs\txt\lib\urllib\request.py", line 247, in urlretrieve
    with contextlib.closing(urlopen(url, data)) as fp:
  File "C:\Users\shiva\.conda\envs\txt\lib\urllib\request.py", line 222, in urlopen
    return opener.open(url, data, timeout)
  File "C:\Users\shiva\.conda\envs\txt\lib\urllib\request.py", line 525, in open
    response = self._open(req, data)
  File "C:\Users\shiva\.conda\envs\txt\lib\urllib\request.py", line 547, in _open
    return self._call_chain(self.handle_open, 'unknown',
  File "C:\Users\shiva\.conda\envs\txt\lib\urllib\request.py", line 502, in _call_chain
    result = func(*args)
  File "C:\Users\shiva\.conda\envs\txt\lib\urllib\request.py", line 1425, in unknown_open
    raise URLError('unknown url type: %s' % type)
urllib.error.URLError: <urlopen error unknown url type: https>
[2023-09-07 10:33:05,242: INFO: common: yaml file: config\config.yaml loaded successfully]
[2023-09-07 10:33:05,242: INFO: common: yaml file: params.yaml loaded successfully]
[2023-09-07 10:33:05,242: INFO: common: created directory at: artifacts]
[2023-09-07 10:33:05,242: INFO: common: created directory at: artifacts/data_ingestion]
[2023-09-07 10:33:07,128: INFO: 1434958058: artifacts/data_ingestion/data.zip download! with following info: 
Connection: close
Content-Length: 7903594
Cache-Control: max-age=300
Content-Security-Policy: default-src 'none'; style-src 'unsafe-inline'; sandbox
Content-Type: application/zip
ETag: "dbc016a060da18070593b83afff580c9b300f0b6ea4147a7988433e04df246ca"
Strict-Transport-Security: max-age=31536000
X-Content-Type-Options: nosniff
X-Frame-Options: deny
X-XSS-Protection: 1; mode=block
X-GitHub-Request-Id: A09E:17B6F8:EE6C6:1594DA:64F95945
Accept-Ranges: bytes
Date: Thu, 07 Sep 2023 05:02:20 GMT
Via: 1.1 varnish
X-Served-By: cache-del21745-DEL
X-Cache: MISS
X-Cache-Hits: 0
X-Timer: S1694062940.598852,VS0,VE757
Vary: Authorization,Accept-Encoding,Origin
Access-Control-Allow-Origin: *
Cross-Origin-Resource-Policy: cross-origin
X-Fastly-Request-ID: 9a5e3473d7b010809701e30fcc30bb26939e99b8
Expires: Thu, 07 Sep 2023 05:07:20 GMT
Source-Age: 0

]
[2023-09-07 10:33:19,080: INFO: common: yaml file: config\config.yaml loaded successfully]
[2023-09-07 10:33:19,080: INFO: common: yaml file: params.yaml loaded successfully]
[2023-09-07 10:33:19,080: INFO: common: created directory at: artifacts]
[2023-09-07 10:33:19,096: INFO: common: created directory at: artifacts/data_validation]
[2023-09-07 10:33:25,834: INFO: common: yaml file: config\config.yaml loaded successfully]
[2023-09-07 10:33:25,834: INFO: common: yaml file: params.yaml loaded successfully]
[2023-09-07 10:33:25,834: INFO: common: created directory at: artifacts]
[2023-09-07 10:33:25,834: INFO: common: created directory at: artifacts/data_transformation]
[2023-09-07 10:33:34,005: INFO: common: yaml file: config\config.yaml loaded successfully]
[2023-09-07 10:33:34,005: INFO: common: yaml file: params.yaml loaded successfully]
[2023-09-07 10:33:34,005: INFO: common: created directory at: artifacts]
[2023-09-07 10:33:34,005: INFO: common: created directory at: artifacts/model_trainer]
[2023-09-07 10:34:20,084: INFO: common: yaml file: config\config.yaml loaded successfully]
[2023-09-07 10:34:20,084: INFO: common: yaml file: params.yaml loaded successfully]
[2023-09-07 10:34:20,084: INFO: common: created directory at: artifacts]
[2023-09-07 10:34:20,084: INFO: common: created directory at: artifacts/model_trainer]
[2023-09-07 10:34:49,044: INFO: common: yaml file: config\config.yaml loaded successfully]
[2023-09-07 10:34:49,044: INFO: common: yaml file: params.yaml loaded successfully]
[2023-09-07 10:34:49,044: INFO: common: created directory at: artifacts]
[2023-09-07 10:34:49,044: INFO: common: created directory at: artifacts/model_trainer]
[2023-09-07 10:35:28,796: INFO: common: yaml file: config\config.yaml loaded successfully]
[2023-09-07 10:35:28,796: INFO: common: yaml file: params.yaml loaded successfully]
[2023-09-07 10:35:28,796: INFO: common: created directory at: artifacts]
[2023-09-07 10:35:28,796: INFO: common: created directory at: artifacts/model_trainer]
[2023-09-07 10:40:44,455: INFO: common: yaml file: config\config.yaml loaded successfully]
[2023-09-07 10:40:44,455: INFO: common: yaml file: params.yaml loaded successfully]
[2023-09-07 10:40:44,471: INFO: common: created directory at: artifacts]
[2023-09-07 10:40:44,471: INFO: common: created directory at: artifacts/model_trainer]
[2023-09-07 10:41:35,449: INFO: common: yaml file: config\config.yaml loaded successfully]
[2023-09-07 10:41:35,449: INFO: common: yaml file: params.yaml loaded successfully]
[2023-09-07 10:41:35,449: INFO: common: created directory at: artifacts]
[2023-09-07 10:41:35,449: INFO: common: created directory at: artifacts/model_trainer]
[2023-09-07 10:42:05,260: INFO: common: yaml file: config\config.yaml loaded successfully]
[2023-09-07 10:42:05,260: INFO: common: yaml file: params.yaml loaded successfully]
[2023-09-07 10:42:05,260: INFO: common: created directory at: artifacts]
[2023-09-07 10:42:05,260: INFO: common: created directory at: artifacts/model_trainer]
[2023-09-07 10:42:24,519: INFO: common: yaml file: config\config.yaml loaded successfully]
[2023-09-07 10:42:24,519: INFO: common: yaml file: params.yaml loaded successfully]
[2023-09-07 10:42:24,519: INFO: common: created directory at: artifacts]
[2023-09-07 10:42:24,519: INFO: common: created directory at: artifacts/model_trainer]
[2023-09-07 10:43:34,347: INFO: common: yaml file: config\config.yaml loaded successfully]
[2023-09-07 10:43:34,347: INFO: common: yaml file: params.yaml loaded successfully]
[2023-09-07 10:43:34,347: INFO: common: created directory at: artifacts]
[2023-09-07 10:43:34,347: INFO: common: created directory at: artifacts/model_trainer]
[2023-09-07 10:47:33,127: INFO: common: yaml file: config\config.yaml loaded successfully]
[2023-09-07 10:47:33,127: INFO: common: yaml file: params.yaml loaded successfully]
[2023-09-07 10:47:33,127: INFO: common: created directory at: artifacts]
[2023-09-07 10:47:33,127: INFO: common: created directory at: artifacts/model_trainer]
[2023-09-07 11:41:27,616: INFO: common: yaml file: config\config.yaml loaded successfully]
[2023-09-07 11:41:27,616: INFO: common: yaml file: params.yaml loaded successfully]
[2023-09-07 11:41:27,616: INFO: common: created directory at: artifacts]
[2023-09-07 11:41:27,616: INFO: common: created directory at: artifacts/data_ingestion]
[2023-09-07 11:41:27,616: INFO: 1434958058: File already exists of size: ~ 7718 KB]
[2023-09-07 11:41:36,248: INFO: common: yaml file: config\config.yaml loaded successfully]
[2023-09-07 11:41:36,248: INFO: common: yaml file: params.yaml loaded successfully]
[2023-09-07 11:41:36,248: INFO: common: created directory at: artifacts]
[2023-09-07 11:41:36,248: INFO: common: created directory at: artifacts/data_validation]
[2023-09-07 11:41:44,845: INFO: common: yaml file: config\config.yaml loaded successfully]
[2023-09-07 11:41:44,845: INFO: common: yaml file: params.yaml loaded successfully]
[2023-09-07 11:41:44,845: INFO: common: created directory at: artifacts]
[2023-09-07 11:41:44,845: INFO: common: created directory at: artifacts/data_transformation]
[2023-09-07 11:41:52,654: INFO: common: yaml file: config\config.yaml loaded successfully]
[2023-09-07 11:41:52,654: INFO: common: yaml file: params.yaml loaded successfully]
[2023-09-07 11:41:52,654: INFO: common: created directory at: artifacts]
[2023-09-07 11:41:52,654: INFO: common: created directory at: artifacts/model_trainer]
[2023-09-07 11:50:21,485: INFO: common: yaml file: config\config.yaml loaded successfully]
[2023-09-07 11:50:21,485: INFO: common: yaml file: params.yaml loaded successfully]
[2023-09-07 11:50:21,485: INFO: common: created directory at: artifacts]
[2023-09-07 11:50:21,485: INFO: common: created directory at: artifacts/data_ingestion]
[2023-09-07 11:50:21,485: INFO: 1434958058: File already exists of size: ~ 7718 KB]
[2023-09-07 11:51:49,169: INFO: common: yaml file: config\config.yaml loaded successfully]
[2023-09-07 11:51:49,169: INFO: common: yaml file: params.yaml loaded successfully]
[2023-09-07 11:51:49,169: INFO: common: created directory at: artifacts]
[2023-09-07 11:51:49,169: INFO: common: created directory at: artifacts/data_ingestion]
[2023-09-07 11:51:49,169: INFO: 1434958058: File already exists of size: ~ 7718 KB]
[2023-09-07 11:51:54,899: INFO: common: yaml file: config\config.yaml loaded successfully]
[2023-09-07 11:51:54,899: INFO: common: yaml file: params.yaml loaded successfully]
[2023-09-07 11:51:54,899: INFO: common: created directory at: artifacts]
[2023-09-07 11:51:54,899: INFO: common: created directory at: artifacts/data_validation]
[2023-09-07 11:52:07,370: INFO: common: yaml file: config\config.yaml loaded successfully]
[2023-09-07 11:52:07,370: INFO: common: yaml file: params.yaml loaded successfully]
[2023-09-07 11:52:07,370: INFO: common: created directory at: artifacts]
[2023-09-07 11:52:07,370: INFO: common: created directory at: artifacts/data_transformation]
[2023-09-07 11:52:20,362: INFO: common: yaml file: config\config.yaml loaded successfully]
[2023-09-07 11:52:20,362: INFO: common: yaml file: params.yaml loaded successfully]
[2023-09-07 11:52:20,362: INFO: common: created directory at: artifacts]
[2023-09-07 11:52:20,362: INFO: common: created directory at: artifacts/model_trainer]
[2023-09-07 16:26:13,862: INFO: main: >>>>>> stage Data Ingestion stage started <<<<<<]
[2023-09-07 16:26:13,878: INFO: common: yaml file: config\config.yaml loaded successfully]
[2023-09-07 16:26:13,878: INFO: common: yaml file: params.yaml loaded successfully]
[2023-09-07 16:26:13,878: INFO: common: created directory at: artifacts]
[2023-09-07 16:26:13,878: INFO: common: created directory at: artifacts/data_ingestion]
[2023-09-07 16:26:13,878: INFO: data_ingestion: File already exists of size: ~ 7718 KB]
[2023-09-07 16:26:13,926: ERROR: main: [Errno 22] Invalid argument: 'artifacts\\data_ingestion\\samsum_dataset\\test\\data-00000-of-00001.arrow']
Traceback (most recent call last):
  File "c:\Users\shiva\OneDrive\Desktop\shivam\Text_Summarization\main.py", line 13, in <module>
    data_ingestion.main()
  File "c:\users\shiva\onedrive\desktop\shivam\text_summarization\src\textSummarizer\pipeline\stage_01_data_ingestion.py", line 15, in main
    data_ingestion.extract_zip_file()
  File "c:\users\shiva\onedrive\desktop\shivam\text_summarization\src\textSummarizer\conponents\data_ingestion.py", line 37, in extract_zip_file
    zip_ref.extractall(unzip_path)
  File "C:\Users\shiva\OneDrive\Desktop\shivam\Text_Summarization\new\lib\zipfile.py", line 1647, in extractall
    self._extract_member(zipinfo, path, pwd)
  File "C:\Users\shiva\OneDrive\Desktop\shivam\Text_Summarization\new\lib\zipfile.py", line 1701, in _extract_member
    open(targetpath, "wb") as target:
OSError: [Errno 22] Invalid argument: 'artifacts\\data_ingestion\\samsum_dataset\\test\\data-00000-of-00001.arrow'
[2023-09-07 16:27:10,099: INFO: main: >>>>>> stage Data Ingestion stage started <<<<<<]
[2023-09-07 16:27:10,099: INFO: common: yaml file: config\config.yaml loaded successfully]
[2023-09-07 16:27:10,099: INFO: common: yaml file: params.yaml loaded successfully]
[2023-09-07 16:27:10,099: INFO: common: created directory at: artifacts]
[2023-09-07 16:27:10,099: INFO: common: created directory at: artifacts/data_ingestion]
[2023-09-07 16:27:10,099: INFO: data_ingestion: File already exists of size: ~ 7718 KB]
[2023-09-07 16:27:10,131: ERROR: main: [Errno 22] Invalid argument: 'artifacts\\data_ingestion\\samsum_dataset\\test\\data-00000-of-00001.arrow']
Traceback (most recent call last):
  File "c:\Users\shiva\OneDrive\Desktop\shivam\Text_Summarization\main.py", line 13, in <module>
    data_ingestion.main()
  File "c:\users\shiva\onedrive\desktop\shivam\text_summarization\src\textSummarizer\pipeline\stage_01_data_ingestion.py", line 15, in main
    data_ingestion.extract_zip_file()
  File "c:\users\shiva\onedrive\desktop\shivam\text_summarization\src\textSummarizer\conponents\data_ingestion.py", line 37, in extract_zip_file
    zip_ref.extractall(unzip_path)
  File "C:\Users\shiva\OneDrive\Desktop\shivam\Text_Summarization\new\lib\zipfile.py", line 1647, in extractall
    self._extract_member(zipinfo, path, pwd)
  File "C:\Users\shiva\OneDrive\Desktop\shivam\Text_Summarization\new\lib\zipfile.py", line 1701, in _extract_member
    open(targetpath, "wb") as target:
OSError: [Errno 22] Invalid argument: 'artifacts\\data_ingestion\\samsum_dataset\\test\\data-00000-of-00001.arrow'
[2023-09-07 16:28:19,817: INFO: main: >>>>>> stage Data Ingestion stage started <<<<<<]
[2023-09-07 16:28:19,817: INFO: common: yaml file: config\config.yaml loaded successfully]
[2023-09-07 16:28:19,817: INFO: common: yaml file: params.yaml loaded successfully]
[2023-09-07 16:28:19,833: INFO: common: created directory at: artifacts]
[2023-09-07 16:28:19,833: INFO: common: created directory at: artifacts/data_ingestion]
[2023-09-07 16:29:02,725: ERROR: main: <urlopen error [WinError 10060] A connection attempt failed because the connected party did not properly respond after a period of time, or established connection failed because connected host has failed to respond>]
Traceback (most recent call last):
  File "C:\Users\shiva\OneDrive\Desktop\shivam\Text_Summarization\new\lib\urllib\request.py", line 1354, in do_open
    h.request(req.get_method(), req.selector, req.data, headers,
  File "C:\Users\shiva\OneDrive\Desktop\shivam\Text_Summarization\new\lib\http\client.py", line 1255, in request
    self._send_request(method, url, body, headers, encode_chunked)
  File "C:\Users\shiva\OneDrive\Desktop\shivam\Text_Summarization\new\lib\http\client.py", line 1301, in _send_request
    self.endheaders(body, encode_chunked=encode_chunked)
  File "C:\Users\shiva\OneDrive\Desktop\shivam\Text_Summarization\new\lib\http\client.py", line 1250, in endheaders
    self._send_output(message_body, encode_chunked=encode_chunked)
  File "C:\Users\shiva\OneDrive\Desktop\shivam\Text_Summarization\new\lib\http\client.py", line 1010, in _send_output
    self.send(msg)
  File "C:\Users\shiva\OneDrive\Desktop\shivam\Text_Summarization\new\lib\http\client.py", line 950, in send
    self.connect()
  File "C:\Users\shiva\OneDrive\Desktop\shivam\Text_Summarization\new\lib\http\client.py", line 1417, in connect
    super().connect()
  File "C:\Users\shiva\OneDrive\Desktop\shivam\Text_Summarization\new\lib\http\client.py", line 921, in connect
    self.sock = self._create_connection(
  File "C:\Users\shiva\OneDrive\Desktop\shivam\Text_Summarization\new\lib\socket.py", line 808, in create_connection
    raise err
  File "C:\Users\shiva\OneDrive\Desktop\shivam\Text_Summarization\new\lib\socket.py", line 796, in create_connection
    sock.connect(sa)
TimeoutError: [WinError 10060] A connection attempt failed because the connected party did not properly respond after a period of time, or established connection failed because connected host has failed to respond

During handling of the above exception, another exception occurred:

Traceback (most recent call last):
  File "c:\Users\shiva\OneDrive\Desktop\shivam\Text_Summarization\main.py", line 13, in <module>
    data_ingestion.main()
  File "c:\users\shiva\onedrive\desktop\shivam\text_summarization\src\textSummarizer\pipeline\stage_01_data_ingestion.py", line 14, in main
    data_ingestion.download_file()
  File "c:\users\shiva\onedrive\desktop\shivam\text_summarization\src\textSummarizer\conponents\data_ingestion.py", line 18, in download_file
    filename, headers = request.urlretrieve(
  File "C:\Users\shiva\OneDrive\Desktop\shivam\Text_Summarization\new\lib\urllib\request.py", line 247, in urlretrieve
    with contextlib.closing(urlopen(url, data)) as fp:
  File "C:\Users\shiva\OneDrive\Desktop\shivam\Text_Summarization\new\lib\urllib\request.py", line 222, in urlopen
    return opener.open(url, data, timeout)
  File "C:\Users\shiva\OneDrive\Desktop\shivam\Text_Summarization\new\lib\urllib\request.py", line 531, in open
    response = meth(req, response)
  File "C:\Users\shiva\OneDrive\Desktop\shivam\Text_Summarization\new\lib\urllib\request.py", line 640, in http_response
    response = self.parent.error(
  File "C:\Users\shiva\OneDrive\Desktop\shivam\Text_Summarization\new\lib\urllib\request.py", line 563, in error
    result = self._call_chain(*args)
  File "C:\Users\shiva\OneDrive\Desktop\shivam\Text_Summarization\new\lib\urllib\request.py", line 502, in _call_chain
    result = func(*args)
  File "C:\Users\shiva\OneDrive\Desktop\shivam\Text_Summarization\new\lib\urllib\request.py", line 755, in http_error_302
    return self.parent.open(new, timeout=req.timeout)
  File "C:\Users\shiva\OneDrive\Desktop\shivam\Text_Summarization\new\lib\urllib\request.py", line 525, in open
    response = self._open(req, data)
  File "C:\Users\shiva\OneDrive\Desktop\shivam\Text_Summarization\new\lib\urllib\request.py", line 542, in _open
    result = self._call_chain(self.handle_open, protocol, protocol +
  File "C:\Users\shiva\OneDrive\Desktop\shivam\Text_Summarization\new\lib\urllib\request.py", line 502, in _call_chain
    result = func(*args)
  File "C:\Users\shiva\OneDrive\Desktop\shivam\Text_Summarization\new\lib\urllib\request.py", line 1397, in https_open
    return self.do_open(http.client.HTTPSConnection, req,
  File "C:\Users\shiva\OneDrive\Desktop\shivam\Text_Summarization\new\lib\urllib\request.py", line 1357, in do_open
    raise URLError(err)
urllib.error.URLError: <urlopen error [WinError 10060] A connection attempt failed because the connected party did not properly respond after a period of time, or established connection failed because connected host has failed to respond>
[2023-09-07 16:34:35,065: INFO: main: >>>>>> stage Data Ingestion stage started <<<<<<]
[2023-09-07 16:34:35,065: INFO: common: yaml file: config\config.yaml loaded successfully]
[2023-09-07 16:34:35,065: INFO: common: yaml file: params.yaml loaded successfully]
[2023-09-07 16:34:35,065: INFO: common: created directory at: artifacts]
[2023-09-07 16:34:35,065: INFO: common: created directory at: artifacts/data_ingestion]
[2023-09-07 16:34:35,065: INFO: data_ingestion: File already exists of size: ~ 7718 KB]
[2023-09-07 16:34:35,144: INFO: main: >>>>>> stage Data Ingestion stage completed <<<<<<

x==========x]
[2023-09-07 16:34:35,144: INFO: main: >>>>>> stage Data Validation stage started <<<<<<]
[2023-09-07 16:34:35,160: INFO: common: yaml file: config\config.yaml loaded successfully]
[2023-09-07 16:34:35,160: INFO: common: yaml file: params.yaml loaded successfully]
[2023-09-07 16:34:35,160: INFO: common: created directory at: artifacts]
[2023-09-07 16:34:35,160: INFO: common: created directory at: artifacts/data_validation]
[2023-09-07 16:34:35,160: INFO: main: >>>>>> stage Data Validation stage completed <<<<<<

x==========x]
[2023-09-07 16:34:35,160: INFO: main: >>>>>> stage Data Transformation stage started <<<<<<]
[2023-09-07 16:34:35,160: INFO: common: yaml file: config\config.yaml loaded successfully]
[2023-09-07 16:34:35,160: INFO: common: yaml file: params.yaml loaded successfully]
[2023-09-07 16:34:35,160: INFO: common: created directory at: artifacts]
[2023-09-07 16:34:35,160: INFO: common: created directory at: artifacts/data_transformation]
[2023-09-07 16:34:37,086: INFO: main: >>>>>> stage Data Transformation stage completed <<<<<<

x==========x]
[2023-09-07 16:34:37,086: INFO: main: *******************]
[2023-09-07 16:34:37,086: INFO: main: >>>>>> stage Model Trainer stage started <<<<<<]
[2023-09-07 16:34:37,086: INFO: common: yaml file: config\config.yaml loaded successfully]
[2023-09-07 16:34:37,086: INFO: common: yaml file: params.yaml loaded successfully]
[2023-09-07 16:34:37,086: INFO: common: created directory at: artifacts]
[2023-09-07 16:34:37,086: INFO: common: created directory at: artifacts/model_trainer]
[2023-09-07 16:35:19,948: INFO: server: Started server process [17800]]
[2023-09-07 16:35:19,948: INFO: on: Waiting for application startup.]
[2023-09-07 16:35:19,948: INFO: on: Application startup complete.]
[2023-09-07 16:35:19,948: INFO: server: Uvicorn running on http://0.0.0.0:8080 (Press CTRL+C to quit)]
[2023-09-07 16:41:45,870: INFO: server: Started server process [9228]]
[2023-09-07 16:41:45,870: INFO: on: Waiting for application startup.]
[2023-09-07 16:41:45,870: INFO: on: Application startup complete.]
[2023-09-07 16:41:45,870: INFO: server: Uvicorn running on http://0.0.0.0:8080 (Press CTRL+C to quit)]
[2023-09-07 16:42:59,503: INFO: server: Shutting down]
[2023-09-07 16:42:59,598: INFO: server: Finished server process [9228]]
[2023-09-07 16:42:59,614: ERROR: on: Traceback (most recent call last):
  File "C:\Users\shiva\OneDrive\Desktop\shivam\Text_Summarization\new\lib\site-packages\starlette\routing.py", line 638, in lifespan
    await receive()
  File "C:\Users\shiva\OneDrive\Desktop\shivam\Text_Summarization\new\lib\site-packages\uvicorn\lifespan\on.py", line 137, in receive
    return await self.receive_queue.get()
  File "C:\Users\shiva\OneDrive\Desktop\shivam\Text_Summarization\new\lib\asyncio\queues.py", line 163, in get
    await getter
asyncio.exceptions.CancelledError
]
[2023-09-07 16:43:02,853: INFO: server: Started server process [19868]]
[2023-09-07 16:43:02,853: INFO: on: Waiting for application startup.]
[2023-09-07 16:43:02,853: INFO: on: Application startup complete.]
[2023-09-07 16:43:02,853: INFO: server: Uvicorn running on http://0.0.0.0:8080 (Press CTRL+C to quit)]
[2023-09-07 16:43:25,674: INFO: server: Shutting down]
[2023-09-07 16:43:25,786: INFO: on: Waiting for application shutdown.]
[2023-09-07 16:43:25,786: INFO: on: Application shutdown complete.]
[2023-09-07 16:43:25,786: INFO: server: Finished server process [19868]]
[2023-09-07 16:44:51,075: INFO: server: Started server process [15952]]
[2023-09-07 16:44:51,075: INFO: on: Waiting for application startup.]
[2023-09-07 16:44:51,075: INFO: on: Application startup complete.]
[2023-09-07 16:44:51,075: INFO: server: Uvicorn running on http://0.0.0.0:3000 (Press CTRL+C to quit)]
[2023-09-07 16:45:26,580: INFO: server: Shutting down]
[2023-09-07 16:45:26,691: INFO: on: Waiting for application shutdown.]
[2023-09-07 16:45:26,691: INFO: on: Application shutdown complete.]
[2023-09-07 16:45:26,691: INFO: server: Finished server process [15952]]
[2023-09-07 16:45:29,688: INFO: server: Started server process [22760]]
[2023-09-07 16:45:29,688: INFO: on: Waiting for application startup.]
[2023-09-07 16:45:29,688: INFO: on: Application startup complete.]
[2023-09-07 16:45:29,688: INFO: server: Uvicorn running on http://0.0.0.0:3000 (Press CTRL+C to quit)]
[2023-09-07 16:45:43,936: INFO: server: Shutting down]
[2023-09-07 16:45:44,032: INFO: server: Finished server process [22760]]
[2023-09-07 16:45:44,032: ERROR: on: Traceback (most recent call last):
  File "C:\Users\shiva\OneDrive\Desktop\shivam\Text_Summarization\new\lib\site-packages\starlette\routing.py", line 638, in lifespan
    await receive()
  File "C:\Users\shiva\OneDrive\Desktop\shivam\Text_Summarization\new\lib\site-packages\uvicorn\lifespan\on.py", line 137, in receive
    return await self.receive_queue.get()
  File "C:\Users\shiva\OneDrive\Desktop\shivam\Text_Summarization\new\lib\asyncio\queues.py", line 163, in get
    await getter
asyncio.exceptions.CancelledError
]
[2023-09-07 16:49:17,827: INFO: server: Started server process [24508]]
[2023-09-07 16:49:17,827: INFO: on: Waiting for application startup.]
[2023-09-07 16:49:17,827: INFO: on: Application startup complete.]
[2023-09-07 16:49:17,827: INFO: server: Uvicorn running on http://localhost:3000 (Press CTRL+C to quit)]
[2023-09-07 16:59:43,374: ERROR: utils: Form data requires "python-multipart" to be installed. 
You can install "python-multipart" with: 

pip install python-multipart
]
[2023-09-07 17:00:00,730: INFO: server: Started server process [16536]]
[2023-09-07 17:00:00,730: INFO: on: Waiting for application startup.]
[2023-09-07 17:00:00,730: INFO: on: Application startup complete.]
[2023-09-07 17:00:00,730: INFO: server: Uvicorn running on http://0.0.0.0:8080 (Press CTRL+C to quit)]
[2023-09-07 17:03:18,676: INFO: server: Shutting down]
[2023-09-07 17:03:18,804: INFO: server: Finished server process [16536]]
[2023-09-07 17:03:18,804: ERROR: on: Traceback (most recent call last):
  File "C:\Users\shiva\OneDrive\Desktop\shivam\Text_Summarization\new\lib\site-packages\starlette\routing.py", line 638, in lifespan
    await receive()
  File "C:\Users\shiva\OneDrive\Desktop\shivam\Text_Summarization\new\lib\site-packages\uvicorn\lifespan\on.py", line 137, in receive
    return await self.receive_queue.get()
  File "C:\Users\shiva\OneDrive\Desktop\shivam\Text_Summarization\new\lib\asyncio\queues.py", line 163, in get
    await getter
asyncio.exceptions.CancelledError
]
[2023-09-07 17:03:23,261: INFO: server: Started server process [2144]]
[2023-09-07 17:03:23,261: INFO: on: Waiting for application startup.]
[2023-09-07 17:03:23,261: INFO: on: Application startup complete.]
[2023-09-07 17:03:23,261: INFO: server: Uvicorn running on http://0.0.0.0:8080 (Press CTRL+C to quit)]
[2023-09-07 17:03:26,923: INFO: server: Shutting down]
[2023-09-07 17:03:27,034: INFO: on: Waiting for application shutdown.]
[2023-09-07 17:03:27,034: INFO: on: Application shutdown complete.]
[2023-09-07 17:03:27,034: INFO: server: Finished server process [2144]]
[2023-09-07 17:03:42,880: INFO: server: Started server process [18296]]
[2023-09-07 17:03:42,880: INFO: on: Waiting for application startup.]
[2023-09-07 17:03:42,880: INFO: on: Application startup complete.]
[2023-09-07 17:03:42,880: ERROR: server: [Errno 11001] getaddrinfo failed]
[2023-09-07 17:03:42,880: INFO: on: Waiting for application shutdown.]
[2023-09-07 17:03:42,880: INFO: on: Application shutdown complete.]
[2023-09-07 17:04:05,269: INFO: server: Started server process [3768]]
[2023-09-07 17:04:05,269: INFO: on: Waiting for application startup.]
[2023-09-07 17:04:05,269: INFO: on: Application startup complete.]
[2023-09-07 17:04:05,269: INFO: server: Uvicorn running on http://localhost:8080 (Press CTRL+C to quit)]
[2023-09-07 17:11:23,689: INFO: server: Started server process [13708]]
[2023-09-07 17:11:23,689: INFO: on: Waiting for application startup.]
[2023-09-07 17:11:23,689: INFO: on: Application startup complete.]
[2023-09-07 17:11:23,689: INFO: server: Uvicorn running on http://localhost:8080 (Press CTRL+C to quit)]
[2023-09-07 17:11:41,502: INFO: server: Shutting down]
[2023-09-07 17:11:41,614: INFO: on: Waiting for application shutdown.]
[2023-09-07 17:11:41,614: INFO: on: Application shutdown complete.]
[2023-09-07 17:11:41,614: INFO: server: Finished server process [13708]]
[2023-09-07 17:13:38,191: INFO: server: Started server process [23092]]
[2023-09-07 17:13:38,191: INFO: on: Waiting for application startup.]
[2023-09-07 17:13:38,191: INFO: on: Application startup complete.]
[2023-09-07 17:13:38,191: INFO: server: Uvicorn running on http://localhost:8080 (Press CTRL+C to quit)]
[2023-09-07 17:14:09,567: INFO: common: yaml file: config\config.yaml loaded successfully]
[2023-09-07 17:14:09,567: INFO: common: yaml file: params.yaml loaded successfully]
[2023-09-07 17:14:09,567: INFO: common: created directory at: artifacts]
[2023-09-07 17:14:09,567: INFO: common: created directory at: artifacts/model_evaluation]
[2023-09-07 17:14:09,567: ERROR: h11_impl: Exception in ASGI application
]
Traceback (most recent call last):
  File "c:\Users\shiva\OneDrive\Desktop\shivam\Text_Summarization\new\lib\site-packages\uvicorn\protocols\http\h11_impl.py", line 404, in run_asgi
    result = await app(  # type: ignore[func-returns-value]
  File "c:\Users\shiva\OneDrive\Desktop\shivam\Text_Summarization\new\lib\site-packages\uvicorn\middleware\proxy_headers.py", line 78, in __call__
    return await self.app(scope, receive, send)
  File "c:\Users\shiva\OneDrive\Desktop\shivam\Text_Summarization\new\lib\site-packages\fastapi\applications.py", line 269, in __call__
    await super().__call__(scope, receive, send)
  File "c:\Users\shiva\OneDrive\Desktop\shivam\Text_Summarization\new\lib\site-packages\starlette\applications.py", line 124, in __call__
    await self.middleware_stack(scope, receive, send)
  File "c:\Users\shiva\OneDrive\Desktop\shivam\Text_Summarization\new\lib\site-packages\starlette\middleware\errors.py", line 184, in __call__
    raise exc
  File "c:\Users\shiva\OneDrive\Desktop\shivam\Text_Summarization\new\lib\site-packages\starlette\middleware\errors.py", line 162, in __call__
    await self.app(scope, receive, _send)
  File "c:\Users\shiva\OneDrive\Desktop\shivam\Text_Summarization\new\lib\site-packages\starlette\exceptions.py", line 93, in __call__
    raise exc
  File "c:\Users\shiva\OneDrive\Desktop\shivam\Text_Summarization\new\lib\site-packages\starlette\exceptions.py", line 82, in __call__
    await self.app(scope, receive, sender)
  File "c:\Users\shiva\OneDrive\Desktop\shivam\Text_Summarization\new\lib\site-packages\fastapi\middleware\asyncexitstack.py", line 21, in __call__
    raise e
  File "c:\Users\shiva\OneDrive\Desktop\shivam\Text_Summarization\new\lib\site-packages\fastapi\middleware\asyncexitstack.py", line 18, in __call__
    await self.app(scope, receive, send)
  File "c:\Users\shiva\OneDrive\Desktop\shivam\Text_Summarization\new\lib\site-packages\starlette\routing.py", line 670, in __call__
    await route.handle(scope, receive, send)
  File "c:\Users\shiva\OneDrive\Desktop\shivam\Text_Summarization\new\lib\site-packages\starlette\routing.py", line 266, in handle
    await self.app(scope, receive, send)
  File "c:\Users\shiva\OneDrive\Desktop\shivam\Text_Summarization\new\lib\site-packages\starlette\routing.py", line 65, in app
    response = await func(request)
  File "c:\Users\shiva\OneDrive\Desktop\shivam\Text_Summarization\new\lib\site-packages\fastapi\routing.py", line 227, in app
    raw_response = await run_endpoint_function(
  File "c:\Users\shiva\OneDrive\Desktop\shivam\Text_Summarization\new\lib\site-packages\fastapi\routing.py", line 160, in run_endpoint_function
    return await dependant.call(**values)
  File "c:\Users\shiva\OneDrive\Desktop\shivam\Text_Summarization\app.py", line 40, in predict_route
    raise e
  File "c:\Users\shiva\OneDrive\Desktop\shivam\Text_Summarization\app.py", line 37, in predict_route
    text = obj.predict(text)
  File "c:\users\shiva\onedrive\desktop\shivam\text_summarization\src\textSummarizer\pipeline\prediction.py", line 13, in predict
    tokenizer = AutoTokenizer.from_pretrained(self.config.tokenizer_path)
  File "c:\Users\shiva\OneDrive\Desktop\shivam\Text_Summarization\new\lib\site-packages\transformers\models\auto\tokenization_auto.py", line 686, in from_pretrained
    tokenizer_config = get_tokenizer_config(pretrained_model_name_or_path, **kwargs)
  File "c:\Users\shiva\OneDrive\Desktop\shivam\Text_Summarization\new\lib\site-packages\transformers\models\auto\tokenization_auto.py", line 519, in get_tokenizer_config
    resolved_config_file = cached_file(
  File "c:\Users\shiva\OneDrive\Desktop\shivam\Text_Summarization\new\lib\site-packages\transformers\utils\hub.py", line 429, in cached_file
    resolved_file = hf_hub_download(
  File "c:\Users\shiva\OneDrive\Desktop\shivam\Text_Summarization\new\lib\site-packages\huggingface_hub\utils\_validators.py", line 110, in _inner_fn
    validate_repo_id(arg_value)
  File "c:\Users\shiva\OneDrive\Desktop\shivam\Text_Summarization\new\lib\site-packages\huggingface_hub\utils\_validators.py", line 158, in validate_repo_id
    raise HFValidationError(
huggingface_hub.utils._validators.HFValidationError: Repo id must be in the form 'repo_name' or 'namespace/repo_name': 'artifacts/model_trainer/tokenizer'. Use `repo_type` argument if needed.
[2023-09-07 17:15:07,016: INFO: server: Shutting down]
[2023-09-07 17:15:07,127: INFO: on: Waiting for application shutdown.]
[2023-09-07 17:15:07,127: INFO: on: Application shutdown complete.]
[2023-09-07 17:15:07,127: INFO: server: Finished server process [23092]]
[2023-09-07 17:15:14,200: INFO: server: Started server process [24384]]
[2023-09-07 17:15:14,200: INFO: on: Waiting for application startup.]
[2023-09-07 17:15:14,200: INFO: on: Application startup complete.]
[2023-09-07 17:15:14,200: INFO: server: Uvicorn running on http://localhost:8080 (Press CTRL+C to quit)]
[2023-09-07 17:15:29,383: INFO: common: yaml file: config\config.yaml loaded successfully]
[2023-09-07 17:15:29,383: INFO: common: yaml file: params.yaml loaded successfully]
[2023-09-07 17:15:29,383: INFO: common: created directory at: artifacts]
[2023-09-07 17:15:29,383: INFO: common: created directory at: artifacts/model_evaluation]
[2023-09-07 17:15:29,383: ERROR: h11_impl: Exception in ASGI application
]
Traceback (most recent call last):
  File "c:\Users\shiva\OneDrive\Desktop\shivam\Text_Summarization\new\lib\site-packages\uvicorn\protocols\http\h11_impl.py", line 404, in run_asgi
    result = await app(  # type: ignore[func-returns-value]
  File "c:\Users\shiva\OneDrive\Desktop\shivam\Text_Summarization\new\lib\site-packages\uvicorn\middleware\proxy_headers.py", line 78, in __call__
    return await self.app(scope, receive, send)
  File "c:\Users\shiva\OneDrive\Desktop\shivam\Text_Summarization\new\lib\site-packages\fastapi\applications.py", line 269, in __call__
    await super().__call__(scope, receive, send)
  File "c:\Users\shiva\OneDrive\Desktop\shivam\Text_Summarization\new\lib\site-packages\starlette\applications.py", line 124, in __call__
    await self.middleware_stack(scope, receive, send)
  File "c:\Users\shiva\OneDrive\Desktop\shivam\Text_Summarization\new\lib\site-packages\starlette\middleware\errors.py", line 184, in __call__
    raise exc
  File "c:\Users\shiva\OneDrive\Desktop\shivam\Text_Summarization\new\lib\site-packages\starlette\middleware\errors.py", line 162, in __call__
    await self.app(scope, receive, _send)
  File "c:\Users\shiva\OneDrive\Desktop\shivam\Text_Summarization\new\lib\site-packages\starlette\exceptions.py", line 93, in __call__
    raise exc
  File "c:\Users\shiva\OneDrive\Desktop\shivam\Text_Summarization\new\lib\site-packages\starlette\exceptions.py", line 82, in __call__
    await self.app(scope, receive, sender)
  File "c:\Users\shiva\OneDrive\Desktop\shivam\Text_Summarization\new\lib\site-packages\fastapi\middleware\asyncexitstack.py", line 21, in __call__
    raise e
  File "c:\Users\shiva\OneDrive\Desktop\shivam\Text_Summarization\new\lib\site-packages\fastapi\middleware\asyncexitstack.py", line 18, in __call__
    await self.app(scope, receive, send)
  File "c:\Users\shiva\OneDrive\Desktop\shivam\Text_Summarization\new\lib\site-packages\starlette\routing.py", line 670, in __call__
    await route.handle(scope, receive, send)
  File "c:\Users\shiva\OneDrive\Desktop\shivam\Text_Summarization\new\lib\site-packages\starlette\routing.py", line 266, in handle
    await self.app(scope, receive, send)
  File "c:\Users\shiva\OneDrive\Desktop\shivam\Text_Summarization\new\lib\site-packages\starlette\routing.py", line 65, in app
    response = await func(request)
  File "c:\Users\shiva\OneDrive\Desktop\shivam\Text_Summarization\new\lib\site-packages\fastapi\routing.py", line 227, in app
    raw_response = await run_endpoint_function(
  File "c:\Users\shiva\OneDrive\Desktop\shivam\Text_Summarization\new\lib\site-packages\fastapi\routing.py", line 160, in run_endpoint_function
    return await dependant.call(**values)
  File "c:\Users\shiva\OneDrive\Desktop\shivam\Text_Summarization\app.py", line 40, in predict_route
    raise e
  File "c:\Users\shiva\OneDrive\Desktop\shivam\Text_Summarization\app.py", line 37, in predict_route
    text = obj.predict(text)
  File "c:\users\shiva\onedrive\desktop\shivam\text_summarization\src\textSummarizer\pipeline\prediction.py", line 13, in predict
    tokenizer = AutoTokenizer.from_pretrained(self.config.tokenizer_path)
  File "c:\Users\shiva\OneDrive\Desktop\shivam\Text_Summarization\new\lib\site-packages\transformers\models\auto\tokenization_auto.py", line 686, in from_pretrained
    tokenizer_config = get_tokenizer_config(pretrained_model_name_or_path, **kwargs)
  File "c:\Users\shiva\OneDrive\Desktop\shivam\Text_Summarization\new\lib\site-packages\transformers\models\auto\tokenization_auto.py", line 519, in get_tokenizer_config
    resolved_config_file = cached_file(
  File "c:\Users\shiva\OneDrive\Desktop\shivam\Text_Summarization\new\lib\site-packages\transformers\utils\hub.py", line 429, in cached_file
    resolved_file = hf_hub_download(
  File "c:\Users\shiva\OneDrive\Desktop\shivam\Text_Summarization\new\lib\site-packages\huggingface_hub\utils\_validators.py", line 110, in _inner_fn
    validate_repo_id(arg_value)
  File "c:\Users\shiva\OneDrive\Desktop\shivam\Text_Summarization\new\lib\site-packages\huggingface_hub\utils\_validators.py", line 158, in validate_repo_id
    raise HFValidationError(
huggingface_hub.utils._validators.HFValidationError: Repo id must be in the form 'repo_name' or 'namespace/repo_name': 'artifacts/model_trainer/tokenizer'. Use `repo_type` argument if needed.
[2023-09-07 17:15:49,437: INFO: server: Shutting down]
[2023-09-07 17:15:49,547: INFO: on: Waiting for application shutdown.]
[2023-09-07 17:15:49,547: INFO: on: Application shutdown complete.]
[2023-09-07 17:15:49,547: INFO: server: Finished server process [24384]]
[2023-09-07 17:20:00,383: INFO: main: >>>>>> stage Data Ingestion stage started <<<<<<]
[2023-09-07 17:20:00,383: INFO: common: yaml file: config\config.yaml loaded successfully]
[2023-09-07 17:20:00,383: INFO: common: yaml file: params.yaml loaded successfully]
[2023-09-07 17:20:00,383: INFO: common: created directory at: artifacts]
[2023-09-07 17:20:00,383: INFO: common: created directory at: artifacts/data_ingestion]
[2023-09-07 17:20:00,383: INFO: data_ingestion: File already exists of size: ~ 7718 KB]
[2023-09-07 17:20:00,463: INFO: main: >>>>>> stage Data Ingestion stage completed <<<<<<

x==========x]
[2023-09-07 17:20:00,463: INFO: main: >>>>>> stage Data Validation stage started <<<<<<]
[2023-09-07 17:20:00,463: INFO: common: yaml file: config\config.yaml loaded successfully]
[2023-09-07 17:20:00,463: INFO: common: yaml file: params.yaml loaded successfully]
[2023-09-07 17:20:00,463: INFO: common: created directory at: artifacts]
[2023-09-07 17:20:00,463: INFO: common: created directory at: artifacts/data_validation]
[2023-09-07 17:20:00,463: INFO: main: >>>>>> stage Data Validation stage completed <<<<<<

x==========x]
[2023-09-07 17:20:00,463: INFO: main: >>>>>> stage Data Transformation stage started <<<<<<]
[2023-09-07 17:20:00,463: INFO: common: yaml file: config\config.yaml loaded successfully]
[2023-09-07 17:20:00,463: INFO: common: yaml file: params.yaml loaded successfully]
[2023-09-07 17:20:00,463: INFO: common: created directory at: artifacts]
[2023-09-07 17:20:00,463: INFO: common: created directory at: artifacts/data_transformation]
[2023-09-07 17:20:01,165: INFO: main: >>>>>> stage Data Transformation stage completed <<<<<<

x==========x]
[2023-09-07 17:20:01,165: INFO: main: *******************]
[2023-09-07 17:20:01,165: INFO: main: >>>>>> stage Model Trainer stage started <<<<<<]
[2023-09-07 17:20:01,165: INFO: common: yaml file: config\config.yaml loaded successfully]
[2023-09-07 17:20:01,165: INFO: common: yaml file: params.yaml loaded successfully]
[2023-09-07 17:20:01,165: INFO: common: created directory at: artifacts]
[2023-09-07 17:20:01,165: INFO: common: created directory at: artifacts/model_trainer]
[2023-09-08 09:33:07,391: INFO: main: >>>>>> stage Data Ingestion stage started <<<<<<]
[2023-09-08 09:33:07,396: INFO: common: yaml file: config\config.yaml loaded successfully]
[2023-09-08 09:33:07,399: INFO: common: yaml file: params.yaml loaded successfully]
[2023-09-08 09:33:07,399: INFO: common: created directory at: artifacts]
[2023-09-08 09:33:07,399: INFO: common: created directory at: artifacts/data_ingestion]
[2023-09-08 09:33:07,400: INFO: data_ingestion: File already exists of size: ~ 7718 KB]
[2023-09-08 09:33:07,478: INFO: main: >>>>>> stage Data Ingestion stage completed <<<<<<

x==========x]
[2023-09-08 09:33:07,478: INFO: main: >>>>>> stage Data Validation stage started <<<<<<]
[2023-09-08 09:33:07,479: INFO: common: yaml file: config\config.yaml loaded successfully]
[2023-09-08 09:33:07,480: INFO: common: yaml file: params.yaml loaded successfully]
[2023-09-08 09:33:07,480: INFO: common: created directory at: artifacts]
[2023-09-08 09:33:07,481: INFO: common: created directory at: artifacts/data_validation]
[2023-09-08 09:33:07,482: INFO: main: >>>>>> stage Data Validation stage completed <<<<<<

x==========x]
[2023-09-08 09:33:07,482: INFO: main: >>>>>> stage Data Transformation stage started <<<<<<]
[2023-09-08 09:33:07,484: INFO: common: yaml file: config\config.yaml loaded successfully]
[2023-09-08 09:33:07,485: INFO: common: yaml file: params.yaml loaded successfully]
[2023-09-08 09:33:07,485: INFO: common: created directory at: artifacts]
[2023-09-08 09:33:07,485: INFO: common: created directory at: artifacts/data_transformation]
[2023-09-08 09:33:08,782: INFO: main: >>>>>> stage Data Transformation stage completed <<<<<<

x==========x]
[2023-09-08 09:33:08,782: INFO: main: *******************]
[2023-09-08 09:33:08,782: INFO: main: >>>>>> stage Model Trainer stage started <<<<<<]
[2023-09-08 09:33:08,784: INFO: common: yaml file: config\config.yaml loaded successfully]
[2023-09-08 09:33:08,785: INFO: common: yaml file: params.yaml loaded successfully]
[2023-09-08 09:33:08,785: INFO: common: created directory at: artifacts]
[2023-09-08 09:33:08,785: INFO: common: created directory at: artifacts/model_trainer]
[2023-09-08 09:47:50,870: INFO: main: >>>>>> stage Model Trainer stage completed <<<<<<

x==========x]
[2023-09-08 09:47:50,871: INFO: main: *******************]
[2023-09-08 09:47:50,871: INFO: main: >>>>>> stage Model Evaluation stage started <<<<<<]
[2023-09-08 09:47:50,872: INFO: common: yaml file: config\config.yaml loaded successfully]
[2023-09-08 09:47:50,873: INFO: common: yaml file: params.yaml loaded successfully]
[2023-09-08 09:47:50,873: INFO: common: created directory at: artifacts]
[2023-09-08 09:47:50,874: INFO: common: created directory at: artifacts/model_evaluation]
[2023-09-08 09:49:11,017: INFO: rouge_scorer: Using default tokenizer.]
[2023-09-08 09:49:11,102: INFO: main: >>>>>> stage Model Evaluation stage completed <<<<<<

x==========x]
[2023-09-08 09:49:35,125: INFO: server: Started server process [24976]]
[2023-09-08 09:49:35,126: INFO: on: Waiting for application startup.]
[2023-09-08 09:49:35,126: INFO: on: Application startup complete.]
[2023-09-08 09:49:35,129: INFO: server: Uvicorn running on http://localhost:8080 (Press CTRL+C to quit)]
[2023-09-08 09:49:56,321: INFO: common: yaml file: config\config.yaml loaded successfully]
[2023-09-08 09:49:56,323: INFO: common: yaml file: params.yaml loaded successfully]
[2023-09-08 09:49:56,324: INFO: common: created directory at: artifacts]
[2023-09-08 09:49:56,325: INFO: common: created directory at: artifacts/model_evaluation]
[2023-09-08 09:50:45,550: INFO: common: yaml file: config\config.yaml loaded successfully]
[2023-09-08 09:50:45,552: INFO: common: yaml file: params.yaml loaded successfully]
[2023-09-08 09:50:45,554: INFO: common: created directory at: artifacts]
[2023-09-08 09:50:45,555: INFO: common: created directory at: artifacts/model_evaluation]
[2023-09-08 09:51:41,372: INFO: server: Shutting down]
[2023-09-08 09:51:41,482: INFO: on: Waiting for application shutdown.]
[2023-09-08 09:51:41,484: INFO: on: Application shutdown complete.]
[2023-09-08 09:51:41,485: INFO: server: Finished server process [24976]]
[2023-09-08 09:51:44,374: INFO: server: Started server process [26308]]
[2023-09-08 09:51:44,375: INFO: on: Waiting for application startup.]
[2023-09-08 09:51:44,375: INFO: on: Application startup complete.]
[2023-09-08 09:51:44,377: INFO: server: Uvicorn running on http://localhost:8080 (Press CTRL+C to quit)]
[2023-09-08 09:51:55,888: INFO: common: yaml file: config\config.yaml loaded successfully]
[2023-09-08 09:51:55,890: INFO: common: yaml file: params.yaml loaded successfully]
[2023-09-08 09:51:55,891: INFO: common: created directory at: artifacts]
[2023-09-08 09:51:55,891: INFO: common: created directory at: artifacts/model_evaluation]
[2023-09-08 09:52:32,482: INFO: main: >>>>>> stage Data Ingestion stage started <<<<<<]
[2023-09-08 09:52:32,483: INFO: common: yaml file: config\config.yaml loaded successfully]
[2023-09-08 09:52:32,484: INFO: common: yaml file: params.yaml loaded successfully]
[2023-09-08 09:52:32,484: INFO: common: created directory at: artifacts]
[2023-09-08 09:52:32,484: INFO: common: created directory at: artifacts/data_ingestion]
[2023-09-08 09:52:32,484: INFO: data_ingestion: File already exists of size: ~ 7718 KB]
[2023-09-08 09:52:32,556: INFO: main: >>>>>> stage Data Ingestion stage completed <<<<<<

x==========x]
[2023-09-08 09:52:32,556: INFO: main: >>>>>> stage Data Validation stage started <<<<<<]
[2023-09-08 09:52:32,558: INFO: common: yaml file: config\config.yaml loaded successfully]
[2023-09-08 09:52:32,558: INFO: common: yaml file: params.yaml loaded successfully]
[2023-09-08 09:52:32,559: INFO: common: created directory at: artifacts]
[2023-09-08 09:52:32,559: INFO: common: created directory at: artifacts/data_validation]
[2023-09-08 09:52:32,560: INFO: main: >>>>>> stage Data Validation stage completed <<<<<<

x==========x]
[2023-09-08 09:52:32,560: INFO: main: >>>>>> stage Data Transformation stage started <<<<<<]
[2023-09-08 09:52:32,562: INFO: common: yaml file: config\config.yaml loaded successfully]
[2023-09-08 09:52:32,563: INFO: common: yaml file: params.yaml loaded successfully]
[2023-09-08 09:52:32,563: INFO: common: created directory at: artifacts]
[2023-09-08 09:52:32,563: INFO: common: created directory at: artifacts/data_transformation]
[2023-09-08 09:52:40,224: INFO: main: >>>>>> stage Data Transformation stage completed <<<<<<

x==========x]
[2023-09-08 09:52:40,224: INFO: main: *******************]
[2023-09-08 09:52:40,225: INFO: main: >>>>>> stage Model Trainer stage started <<<<<<]
[2023-09-08 09:52:40,227: INFO: common: yaml file: config\config.yaml loaded successfully]
[2023-09-08 09:52:40,227: INFO: common: yaml file: params.yaml loaded successfully]
[2023-09-08 09:52:40,228: INFO: common: created directory at: artifacts]
[2023-09-08 09:52:40,228: INFO: common: created directory at: artifacts/model_trainer]
[2023-09-08 09:53:06,004: INFO: server: Shutting down]
[2023-09-08 09:53:06,113: INFO: server: Finished server process [26308]]
[2023-09-08 09:53:06,130: ERROR: on: Traceback (most recent call last):
  File "c:\Users\shiva\OneDrive\Desktop\shivam\Text_Summarization\new\lib\site-packages\starlette\routing.py", line 638, in lifespan
    await receive()
  File "c:\Users\shiva\OneDrive\Desktop\shivam\Text_Summarization\new\lib\site-packages\uvicorn\lifespan\on.py", line 137, in receive
    return await self.receive_queue.get()
  File "c:\Users\shiva\OneDrive\Desktop\shivam\Text_Summarization\new\lib\asyncio\queues.py", line 163, in get
    await getter
asyncio.exceptions.CancelledError
]
[2023-09-08 10:08:56,149: INFO: server: Started server process [25984]]
[2023-09-08 10:08:56,150: INFO: on: Waiting for application startup.]
[2023-09-08 10:08:56,150: INFO: on: Application startup complete.]
[2023-09-08 10:08:56,150: INFO: server: Uvicorn running on http://0.0.0.0:3000 (Press CTRL+C to quit)]
[2023-09-08 10:09:31,356: INFO: server: Shutting down]
[2023-09-08 10:09:31,467: INFO: on: Waiting for application shutdown.]
[2023-09-08 10:09:31,467: INFO: on: Application shutdown complete.]
[2023-09-08 10:09:31,468: INFO: server: Finished server process [25984]]
[2023-09-08 10:09:58,033: INFO: server: Started server process [2088]]
[2023-09-08 10:09:58,033: INFO: on: Waiting for application startup.]
[2023-09-08 10:09:58,034: INFO: on: Application startup complete.]
[2023-09-08 10:09:58,034: INFO: server: Uvicorn running on http://0.0.0.0:8080 (Press CTRL+C to quit)]
[2023-09-08 10:10:17,888: INFO: server: Shutting down]
[2023-09-08 10:10:17,999: INFO: on: Waiting for application shutdown.]
[2023-09-08 10:10:17,999: INFO: on: Application shutdown complete.]
[2023-09-08 10:10:17,999: INFO: server: Finished server process [2088]]
[2023-09-08 10:10:41,475: INFO: server: Started server process [21608]]
[2023-09-08 10:10:41,475: INFO: on: Waiting for application startup.]
[2023-09-08 10:10:41,475: INFO: on: Application startup complete.]
[2023-09-08 10:10:41,476: INFO: server: Uvicorn running on http://0.0.0.0:8080 (Press CTRL+C to quit)]
[2023-09-08 10:10:51,392: INFO: server: Shutting down]
[2023-09-08 10:10:51,504: INFO: on: Waiting for application shutdown.]
[2023-09-08 10:10:51,505: INFO: on: Application shutdown complete.]
[2023-09-08 10:10:51,505: INFO: server: Finished server process [21608]]
[2023-09-08 10:11:20,289: INFO: server: Started server process [24528]]
[2023-09-08 10:11:20,289: INFO: on: Waiting for application startup.]
[2023-09-08 10:11:20,289: INFO: on: Application startup complete.]
[2023-09-08 10:11:20,292: INFO: server: Uvicorn running on http://localhost:8080 (Press CTRL+C to quit)]
[2023-09-08 10:11:26,502: INFO: server: Shutting down]
[2023-09-08 10:11:26,610: INFO: on: Waiting for application shutdown.]
[2023-09-08 10:11:26,611: INFO: on: Application shutdown complete.]
[2023-09-08 10:11:26,612: INFO: server: Finished server process [24528]]
[2023-09-08 10:11:40,920: INFO: server: Started server process [27144]]
[2023-09-08 10:11:40,920: INFO: on: Waiting for application startup.]
[2023-09-08 10:11:40,921: INFO: on: Application startup complete.]
[2023-09-08 10:11:40,921: INFO: server: Uvicorn running on http://0.0.0.0:8080 (Press CTRL+C to quit)]
[2023-09-08 10:12:08,842: INFO: main: >>>>>> stage Data Ingestion stage started <<<<<<]
[2023-09-08 10:12:08,844: INFO: common: yaml file: config\config.yaml loaded successfully]
[2023-09-08 10:12:08,845: INFO: common: yaml file: params.yaml loaded successfully]
[2023-09-08 10:12:08,845: INFO: common: created directory at: artifacts]
[2023-09-08 10:12:08,845: INFO: common: created directory at: artifacts/data_ingestion]
[2023-09-08 10:12:51,465: ERROR: main: <urlopen error [WinError 10060] A connection attempt failed because the connected party did not properly respond after a period of time, or established connection failed because connected host has failed to respond>]
Traceback (most recent call last):
  File "C:\Users\shiva\OneDrive\Desktop\shivam\Text_Summarization\helloo\lib\urllib\request.py", line 1354, in do_open
    h.request(req.get_method(), req.selector, req.data, headers,
  File "C:\Users\shiva\OneDrive\Desktop\shivam\Text_Summarization\helloo\lib\http\client.py", line 1255, in request
    self._send_request(method, url, body, headers, encode_chunked)
  File "C:\Users\shiva\OneDrive\Desktop\shivam\Text_Summarization\helloo\lib\http\client.py", line 1301, in _send_request
    self.endheaders(body, encode_chunked=encode_chunked)
  File "C:\Users\shiva\OneDrive\Desktop\shivam\Text_Summarization\helloo\lib\http\client.py", line 1250, in endheaders
    self._send_output(message_body, encode_chunked=encode_chunked)
  File "C:\Users\shiva\OneDrive\Desktop\shivam\Text_Summarization\helloo\lib\http\client.py", line 1010, in _send_output
    self.send(msg)
  File "C:\Users\shiva\OneDrive\Desktop\shivam\Text_Summarization\helloo\lib\http\client.py", line 950, in send
    self.connect()
  File "C:\Users\shiva\OneDrive\Desktop\shivam\Text_Summarization\helloo\lib\http\client.py", line 1417, in connect
    super().connect()
  File "C:\Users\shiva\OneDrive\Desktop\shivam\Text_Summarization\helloo\lib\http\client.py", line 921, in connect
    self.sock = self._create_connection(
  File "C:\Users\shiva\OneDrive\Desktop\shivam\Text_Summarization\helloo\lib\socket.py", line 808, in create_connection
    raise err
  File "C:\Users\shiva\OneDrive\Desktop\shivam\Text_Summarization\helloo\lib\socket.py", line 796, in create_connection
    sock.connect(sa)
TimeoutError: [WinError 10060] A connection attempt failed because the connected party did not properly respond after a period of time, or established connection failed because connected host has failed to respond

During handling of the above exception, another exception occurred:

Traceback (most recent call last):
  File "main.py", line 13, in <module>
    data_ingestion.main()
  File "c:\users\shiva\onedrive\desktop\shivam\text_summarization\src\textSummarizer\pipeline\stage_01_data_ingestion.py", line 14, in main
    data_ingestion.download_file()
  File "c:\users\shiva\onedrive\desktop\shivam\text_summarization\src\textSummarizer\conponents\data_ingestion.py", line 18, in download_file
    filename, headers = request.urlretrieve(
  File "C:\Users\shiva\OneDrive\Desktop\shivam\Text_Summarization\helloo\lib\urllib\request.py", line 247, in urlretrieve
    with contextlib.closing(urlopen(url, data)) as fp:
  File "C:\Users\shiva\OneDrive\Desktop\shivam\Text_Summarization\helloo\lib\urllib\request.py", line 222, in urlopen
    return opener.open(url, data, timeout)
  File "C:\Users\shiva\OneDrive\Desktop\shivam\Text_Summarization\helloo\lib\urllib\request.py", line 531, in open
    response = meth(req, response)
  File "C:\Users\shiva\OneDrive\Desktop\shivam\Text_Summarization\helloo\lib\urllib\request.py", line 640, in http_response
    response = self.parent.error(
  File "C:\Users\shiva\OneDrive\Desktop\shivam\Text_Summarization\helloo\lib\urllib\request.py", line 563, in error
    result = self._call_chain(*args)
  File "C:\Users\shiva\OneDrive\Desktop\shivam\Text_Summarization\helloo\lib\urllib\request.py", line 502, in _call_chain
    result = func(*args)
  File "C:\Users\shiva\OneDrive\Desktop\shivam\Text_Summarization\helloo\lib\urllib\request.py", line 755, in http_error_302
    return self.parent.open(new, timeout=req.timeout)
  File "C:\Users\shiva\OneDrive\Desktop\shivam\Text_Summarization\helloo\lib\urllib\request.py", line 525, in open
    response = self._open(req, data)
  File "C:\Users\shiva\OneDrive\Desktop\shivam\Text_Summarization\helloo\lib\urllib\request.py", line 542, in _open
    result = self._call_chain(self.handle_open, protocol, protocol +
  File "C:\Users\shiva\OneDrive\Desktop\shivam\Text_Summarization\helloo\lib\urllib\request.py", line 502, in _call_chain
    result = func(*args)
  File "C:\Users\shiva\OneDrive\Desktop\shivam\Text_Summarization\helloo\lib\urllib\request.py", line 1397, in https_open
    return self.do_open(http.client.HTTPSConnection, req,
  File "C:\Users\shiva\OneDrive\Desktop\shivam\Text_Summarization\helloo\lib\urllib\request.py", line 1357, in do_open
    raise URLError(err)
urllib.error.URLError: <urlopen error [WinError 10060] A connection attempt failed because the connected party did not properly respond after a period of time, or established connection failed because connected host has failed to respond>
[2023-09-08 10:13:34,103: INFO: server: Shutting down]
[2023-09-08 10:13:34,211: INFO: on: Waiting for application shutdown.]
[2023-09-08 10:13:34,212: INFO: on: Application shutdown complete.]
[2023-09-08 10:13:34,213: INFO: server: Finished server process [27144]]
[2023-09-08 10:13:43,157: INFO: server: Started server process [12376]]
[2023-09-08 10:13:43,158: INFO: on: Waiting for application startup.]
[2023-09-08 10:13:43,158: INFO: on: Application startup complete.]
[2023-09-08 10:13:43,158: INFO: server: Uvicorn running on http://0.0.0.0:8080 (Press CTRL+C to quit)]
[2023-09-08 10:14:04,155: INFO: main: >>>>>> stage Data Ingestion stage started <<<<<<]
[2023-09-08 10:14:04,156: INFO: common: yaml file: config\config.yaml loaded successfully]
[2023-09-08 10:14:04,157: INFO: common: yaml file: params.yaml loaded successfully]
[2023-09-08 10:14:04,157: INFO: common: created directory at: artifacts]
[2023-09-08 10:14:04,158: INFO: common: created directory at: artifacts/data_ingestion]
[2023-09-08 10:14:04,158: INFO: main: >>>>>> stage Data Ingestion stage completed <<<<<<

x==========x]
[2023-09-08 10:14:04,158: INFO: main: >>>>>> stage Data Validation stage started <<<<<<]
[2023-09-08 10:14:04,159: INFO: common: yaml file: config\config.yaml loaded successfully]
[2023-09-08 10:14:04,160: INFO: common: yaml file: params.yaml loaded successfully]
[2023-09-08 10:14:04,160: INFO: common: created directory at: artifacts]
[2023-09-08 10:14:04,161: INFO: common: created directory at: artifacts/data_validation]
[2023-09-08 10:14:04,162: INFO: main: >>>>>> stage Data Validation stage completed <<<<<<

x==========x]
[2023-09-08 10:14:04,162: INFO: main: >>>>>> stage Data Transformation stage started <<<<<<]
[2023-09-08 10:14:04,164: INFO: common: yaml file: config\config.yaml loaded successfully]
[2023-09-08 10:14:04,164: INFO: common: yaml file: params.yaml loaded successfully]
[2023-09-08 10:14:04,165: INFO: common: created directory at: artifacts]
[2023-09-08 10:14:04,165: INFO: common: created directory at: artifacts/data_transformation]
[2023-09-08 10:14:05,063: ERROR: main: No such files: 'artifacts/data_ingestion/samsum_dataset\train\dataset_info.json', nor 'artifacts/data_ingestion/samsum_dataset\train\state.json' found. Expected to load a `Dataset` object but provided path is not a `Dataset`.]
Traceback (most recent call last):
  File "main.py", line 38, in <module>
    data_transformation.main()
  File "c:\users\shiva\onedrive\desktop\shivam\text_summarization\src\textSummarizer\pipeline\stage_03_data_transformation.py", line 14, in main
    data_transformation.convert()
  File "c:\users\shiva\onedrive\desktop\shivam\text_summarization\src\textSummarizer\conponents\data_transformation.py", line 30, in convert
    dataset_samsum = load_from_disk(self.config.data_path)
  File "C:\Users\shiva\OneDrive\Desktop\shivam\Text_Summarization\helloo\lib\site-packages\datasets\load.py", line 2250, in load_from_disk
    return DatasetDict.load_from_disk(dataset_path, keep_in_memory=keep_in_memory, storage_options=storage_options)
  File "C:\Users\shiva\OneDrive\Desktop\shivam\Text_Summarization\helloo\lib\site-packages\datasets\dataset_dict.py", line 1371, in load_from_disk
    dataset_dict[k] = Dataset.load_from_disk(
  File "C:\Users\shiva\OneDrive\Desktop\shivam\Text_Summarization\helloo\lib\site-packages\datasets\arrow_dataset.py", line 1671, in load_from_disk
    raise FileNotFoundError(
FileNotFoundError: No such files: 'artifacts/data_ingestion/samsum_dataset\train\dataset_info.json', nor 'artifacts/data_ingestion/samsum_dataset\train\state.json' found. Expected to load a `Dataset` object but provided path is not a `Dataset`.
[2023-09-08 10:16:38,658: INFO: server: Shutting down]
[2023-09-08 10:16:38,767: INFO: on: Waiting for application shutdown.]
[2023-09-08 10:16:38,769: INFO: on: Application shutdown complete.]
[2023-09-08 10:16:38,769: INFO: server: Finished server process [12376]]
[2023-09-08 10:16:43,407: INFO: server: Started server process [14456]]
[2023-09-08 10:16:43,408: INFO: on: Waiting for application startup.]
[2023-09-08 10:16:43,408: INFO: on: Application startup complete.]
[2023-09-08 10:16:43,409: INFO: server: Uvicorn running on http://0.0.0.0:8080 (Press CTRL+C to quit)]
[2023-09-08 10:16:49,208: INFO: main: >>>>>> stage Data Ingestion stage started <<<<<<]
[2023-09-08 10:16:49,210: INFO: common: yaml file: config\config.yaml loaded successfully]
[2023-09-08 10:16:49,210: INFO: common: yaml file: params.yaml loaded successfully]
[2023-09-08 10:16:49,211: INFO: common: created directory at: artifacts]
[2023-09-08 10:16:49,211: INFO: common: created directory at: artifacts/data_ingestion]
[2023-09-08 10:16:49,211: INFO: main: >>>>>> stage Data Ingestion stage completed <<<<<<

x==========x]
[2023-09-08 10:16:49,211: INFO: main: >>>>>> stage Data Validation stage started <<<<<<]
[2023-09-08 10:16:49,212: INFO: common: yaml file: config\config.yaml loaded successfully]
[2023-09-08 10:16:49,213: INFO: common: yaml file: params.yaml loaded successfully]
[2023-09-08 10:16:49,214: INFO: common: created directory at: artifacts]
[2023-09-08 10:16:49,214: INFO: common: created directory at: artifacts/data_validation]
[2023-09-08 10:16:49,215: INFO: main: >>>>>> stage Data Validation stage completed <<<<<<

x==========x]
[2023-09-08 10:16:49,215: INFO: main: >>>>>> stage Data Transformation stage started <<<<<<]
[2023-09-08 10:16:49,217: INFO: common: yaml file: config\config.yaml loaded successfully]
[2023-09-08 10:16:49,217: INFO: common: yaml file: params.yaml loaded successfully]
[2023-09-08 10:16:49,217: INFO: common: created directory at: artifacts]
[2023-09-08 10:16:49,218: INFO: common: created directory at: artifacts/data_transformation]
[2023-09-08 10:16:50,166: ERROR: main: No such files: 'artifacts/data_ingestion/samsum_dataset\train\dataset_info.json', nor 'artifacts/data_ingestion/samsum_dataset\train\state.json' found. Expected to load a `Dataset` object but provided path is not a `Dataset`.]
Traceback (most recent call last):
  File "main.py", line 38, in <module>
    data_transformation.main()
  File "c:\users\shiva\onedrive\desktop\shivam\text_summarization\src\textSummarizer\pipeline\stage_03_data_transformation.py", line 14, in main
    data_transformation.convert()
  File "c:\users\shiva\onedrive\desktop\shivam\text_summarization\src\textSummarizer\conponents\data_transformation.py", line 30, in convert
    dataset_samsum = load_from_disk(self.config.data_path)
  File "C:\Users\shiva\OneDrive\Desktop\shivam\Text_Summarization\helloo\lib\site-packages\datasets\load.py", line 2250, in load_from_disk
    return DatasetDict.load_from_disk(dataset_path, keep_in_memory=keep_in_memory, storage_options=storage_options)
  File "C:\Users\shiva\OneDrive\Desktop\shivam\Text_Summarization\helloo\lib\site-packages\datasets\dataset_dict.py", line 1371, in load_from_disk
    dataset_dict[k] = Dataset.load_from_disk(
  File "C:\Users\shiva\OneDrive\Desktop\shivam\Text_Summarization\helloo\lib\site-packages\datasets\arrow_dataset.py", line 1671, in load_from_disk
    raise FileNotFoundError(
FileNotFoundError: No such files: 'artifacts/data_ingestion/samsum_dataset\train\dataset_info.json', nor 'artifacts/data_ingestion/samsum_dataset\train\state.json' found. Expected to load a `Dataset` object but provided path is not a `Dataset`.
[2023-09-08 10:21:35,279: INFO: server: Shutting down]
[2023-09-08 10:21:35,388: INFO: on: Waiting for application shutdown.]
[2023-09-08 10:21:35,388: INFO: on: Application shutdown complete.]
[2023-09-08 10:21:35,388: INFO: server: Finished server process [14456]]
[2023-09-08 10:21:42,849: INFO: main: >>>>>> stage Data Ingestion stage started <<<<<<]
[2023-09-08 10:21:42,851: INFO: common: yaml file: config\config.yaml loaded successfully]
[2023-09-08 10:21:42,851: INFO: common: yaml file: params.yaml loaded successfully]
[2023-09-08 10:21:42,852: INFO: common: created directory at: artifacts]
[2023-09-08 10:21:42,852: INFO: common: created directory at: artifacts/data_ingestion]
[2023-09-08 10:21:42,852: INFO: main: >>>>>> stage Data Ingestion stage completed <<<<<<

x==========x]
[2023-09-08 10:21:42,852: INFO: main: >>>>>> stage Data Validation stage started <<<<<<]
[2023-09-08 10:21:42,853: INFO: common: yaml file: config\config.yaml loaded successfully]
[2023-09-08 10:21:42,854: INFO: common: yaml file: params.yaml loaded successfully]
[2023-09-08 10:21:42,855: INFO: common: created directory at: artifacts]
[2023-09-08 10:21:42,855: INFO: common: created directory at: artifacts/data_validation]
[2023-09-08 10:21:42,856: INFO: main: >>>>>> stage Data Validation stage completed <<<<<<

x==========x]
[2023-09-08 10:21:42,856: INFO: main: >>>>>> stage Data Transformation stage started <<<<<<]
[2023-09-08 10:21:42,859: INFO: common: yaml file: config\config.yaml loaded successfully]
[2023-09-08 10:21:42,861: INFO: common: yaml file: params.yaml loaded successfully]
[2023-09-08 10:21:42,861: INFO: common: created directory at: artifacts]
[2023-09-08 10:21:42,861: INFO: common: created directory at: artifacts/data_transformation]
[2023-09-08 10:21:43,773: ERROR: main: No such files: 'artifacts/data_ingestion/samsum_dataset\train\dataset_info.json', nor 'artifacts/data_ingestion/samsum_dataset\train\state.json' found. Expected to load a `Dataset` object but provided path is not a `Dataset`.]
Traceback (most recent call last):
  File "c:\Users\shiva\OneDrive\Desktop\shivam\Text_Summarization\main.py", line 38, in <module>
    data_transformation.main()
  File "c:\users\shiva\onedrive\desktop\shivam\text_summarization\src\textSummarizer\pipeline\stage_03_data_transformation.py", line 14, in main
    data_transformation.convert()
  File "c:\users\shiva\onedrive\desktop\shivam\text_summarization\src\textSummarizer\conponents\data_transformation.py", line 30, in convert
    dataset_samsum = load_from_disk(self.config.data_path)
  File "C:\Users\shiva\OneDrive\Desktop\shivam\Text_Summarization\helloo\lib\site-packages\datasets\load.py", line 2250, in load_from_disk
    return DatasetDict.load_from_disk(dataset_path, keep_in_memory=keep_in_memory, storage_options=storage_options)
  File "C:\Users\shiva\OneDrive\Desktop\shivam\Text_Summarization\helloo\lib\site-packages\datasets\dataset_dict.py", line 1371, in load_from_disk
    dataset_dict[k] = Dataset.load_from_disk(
  File "C:\Users\shiva\OneDrive\Desktop\shivam\Text_Summarization\helloo\lib\site-packages\datasets\arrow_dataset.py", line 1671, in load_from_disk
    raise FileNotFoundError(
FileNotFoundError: No such files: 'artifacts/data_ingestion/samsum_dataset\train\dataset_info.json', nor 'artifacts/data_ingestion/samsum_dataset\train\state.json' found. Expected to load a `Dataset` object but provided path is not a `Dataset`.
[2023-09-08 10:25:04,198: INFO: main: >>>>>> stage Data Ingestion stage started <<<<<<]
[2023-09-08 10:25:04,199: INFO: common: yaml file: config\config.yaml loaded successfully]
[2023-09-08 10:25:04,200: INFO: common: yaml file: params.yaml loaded successfully]
[2023-09-08 10:25:04,201: INFO: common: created directory at: artifacts]
[2023-09-08 10:25:04,201: INFO: common: created directory at: artifacts/data_ingestion]
[2023-09-08 10:25:04,201: INFO: main: >>>>>> stage Data Ingestion stage completed <<<<<<

x==========x]
[2023-09-08 10:25:04,201: INFO: main: >>>>>> stage Data Validation stage started <<<<<<]
[2023-09-08 10:25:04,203: INFO: common: yaml file: config\config.yaml loaded successfully]
[2023-09-08 10:25:04,204: INFO: common: yaml file: params.yaml loaded successfully]
[2023-09-08 10:25:04,204: INFO: common: created directory at: artifacts]
[2023-09-08 10:25:04,204: INFO: common: created directory at: artifacts/data_validation]
[2023-09-08 10:25:04,205: INFO: main: >>>>>> stage Data Validation stage completed <<<<<<

x==========x]
[2023-09-08 10:25:04,205: INFO: main: >>>>>> stage Data Transformation stage started <<<<<<]
[2023-09-08 10:25:04,209: INFO: common: yaml file: config\config.yaml loaded successfully]
[2023-09-08 10:25:04,210: INFO: common: yaml file: params.yaml loaded successfully]
[2023-09-08 10:25:04,210: INFO: common: created directory at: artifacts]
[2023-09-08 10:25:04,211: INFO: common: created directory at: artifacts/data_transformation]
[2023-09-08 10:25:05,167: ERROR: main: No such files: 'artifacts/data_ingestion/samsum_dataset\train\dataset_info.json', nor 'artifacts/data_ingestion/samsum_dataset\train\state.json' found. Expected to load a `Dataset` object but provided path is not a `Dataset`.]
Traceback (most recent call last):
  File "c:\Users\shiva\OneDrive\Desktop\shivam\Text_Summarization\main.py", line 38, in <module>
    data_transformation.main()
  File "c:\users\shiva\onedrive\desktop\shivam\text_summarization\src\textSummarizer\pipeline\stage_03_data_transformation.py", line 14, in main
    data_transformation.convert()
  File "c:\users\shiva\onedrive\desktop\shivam\text_summarization\src\textSummarizer\conponents\data_transformation.py", line 31, in convert
    dataset_samsum = load_from_disk(self.config.data_path)
  File "C:\Users\shiva\OneDrive\Desktop\shivam\Text_Summarization\helloo\lib\site-packages\datasets\load.py", line 2250, in load_from_disk
    return DatasetDict.load_from_disk(dataset_path, keep_in_memory=keep_in_memory, storage_options=storage_options)
  File "C:\Users\shiva\OneDrive\Desktop\shivam\Text_Summarization\helloo\lib\site-packages\datasets\dataset_dict.py", line 1371, in load_from_disk
    dataset_dict[k] = Dataset.load_from_disk(
  File "C:\Users\shiva\OneDrive\Desktop\shivam\Text_Summarization\helloo\lib\site-packages\datasets\arrow_dataset.py", line 1671, in load_from_disk
    raise FileNotFoundError(
FileNotFoundError: No such files: 'artifacts/data_ingestion/samsum_dataset\train\dataset_info.json', nor 'artifacts/data_ingestion/samsum_dataset\train\state.json' found. Expected to load a `Dataset` object but provided path is not a `Dataset`.
[2023-09-08 10:27:54,025: INFO: main: >>>>>> stage Data Ingestion stage started <<<<<<]
[2023-09-08 10:27:54,027: INFO: common: yaml file: config\config.yaml loaded successfully]
[2023-09-08 10:27:54,028: INFO: common: yaml file: params.yaml loaded successfully]
[2023-09-08 10:27:54,028: INFO: common: created directory at: artifacts]
[2023-09-08 10:27:54,029: INFO: common: created directory at: artifacts/data_ingestion]
[2023-09-08 10:27:54,029: INFO: main: >>>>>> stage Data Ingestion stage completed <<<<<<

x==========x]
[2023-09-08 10:27:54,029: INFO: main: >>>>>> stage Data Validation stage started <<<<<<]
[2023-09-08 10:27:54,030: INFO: common: yaml file: config\config.yaml loaded successfully]
[2023-09-08 10:27:54,031: INFO: common: yaml file: params.yaml loaded successfully]
[2023-09-08 10:27:54,031: INFO: common: created directory at: artifacts]
[2023-09-08 10:27:54,032: INFO: common: created directory at: artifacts/data_validation]
[2023-09-08 10:27:54,032: INFO: main: >>>>>> stage Data Validation stage completed <<<<<<

x==========x]
[2023-09-08 10:27:54,033: INFO: main: >>>>>> stage Data Transformation stage started <<<<<<]
[2023-09-08 10:27:54,036: INFO: common: yaml file: config\config.yaml loaded successfully]
[2023-09-08 10:27:54,037: INFO: common: yaml file: params.yaml loaded successfully]
[2023-09-08 10:27:54,037: INFO: common: created directory at: artifacts]
[2023-09-08 10:27:54,037: INFO: common: created directory at: artifacts/data_transformation]
[2023-09-08 10:27:54,534: ERROR: main: No such files: 'artifacts/data_ingestion/samsum_dataset\train\dataset_info.json', nor 'artifacts/data_ingestion/samsum_dataset\train\state.json' found. Expected to load a `Dataset` object but provided path is not a `Dataset`.]
Traceback (most recent call last):
  File "c:\Users\shiva\OneDrive\Desktop\shivam\Text_Summarization\main.py", line 38, in <module>
    data_transformation.main()
  File "c:\users\shiva\onedrive\desktop\shivam\text_summarization\src\textSummarizer\pipeline\stage_03_data_transformation.py", line 14, in main
    data_transformation.convert()
  File "c:\users\shiva\onedrive\desktop\shivam\text_summarization\src\textSummarizer\conponents\data_transformation.py", line 33, in convert
    dataset_samsum = load_from_disk(self.config.data_path)
  File "C:\Users\shiva\OneDrive\Desktop\shivam\Text_Summarization\helloo\lib\site-packages\datasets\load.py", line 2250, in load_from_disk
    return DatasetDict.load_from_disk(dataset_path, keep_in_memory=keep_in_memory, storage_options=storage_options)
  File "C:\Users\shiva\OneDrive\Desktop\shivam\Text_Summarization\helloo\lib\site-packages\datasets\dataset_dict.py", line 1371, in load_from_disk
    dataset_dict[k] = Dataset.load_from_disk(
  File "C:\Users\shiva\OneDrive\Desktop\shivam\Text_Summarization\helloo\lib\site-packages\datasets\arrow_dataset.py", line 1671, in load_from_disk
    raise FileNotFoundError(
FileNotFoundError: No such files: 'artifacts/data_ingestion/samsum_dataset\train\dataset_info.json', nor 'artifacts/data_ingestion/samsum_dataset\train\state.json' found. Expected to load a `Dataset` object but provided path is not a `Dataset`.
[2023-09-08 10:29:52,476: INFO: main: >>>>>> stage Data Ingestion stage started <<<<<<]
[2023-09-08 10:29:52,478: INFO: common: yaml file: config\config.yaml loaded successfully]
[2023-09-08 10:29:52,479: INFO: common: yaml file: params.yaml loaded successfully]
[2023-09-08 10:29:52,479: INFO: common: created directory at: artifacts]
[2023-09-08 10:29:52,479: INFO: common: created directory at: artifacts/data_ingestion]
[2023-09-08 10:29:52,479: INFO: main: >>>>>> stage Data Ingestion stage completed <<<<<<

x==========x]
[2023-09-08 10:29:52,479: INFO: main: >>>>>> stage Data Validation stage started <<<<<<]
[2023-09-08 10:29:52,481: INFO: common: yaml file: config\config.yaml loaded successfully]
[2023-09-08 10:29:52,482: INFO: common: yaml file: params.yaml loaded successfully]
[2023-09-08 10:29:52,482: INFO: common: created directory at: artifacts]
[2023-09-08 10:29:52,482: INFO: common: created directory at: artifacts/data_validation]
[2023-09-08 10:29:52,483: INFO: main: >>>>>> stage Data Validation stage completed <<<<<<

x==========x]
[2023-09-08 10:29:52,483: INFO: main: >>>>>> stage Data Transformation stage started <<<<<<]
[2023-09-08 10:29:52,485: INFO: common: yaml file: config\config.yaml loaded successfully]
[2023-09-08 10:29:52,486: INFO: common: yaml file: params.yaml loaded successfully]
[2023-09-08 10:29:52,486: INFO: common: created directory at: artifacts]
[2023-09-08 10:29:52,486: INFO: common: created directory at: artifacts/data_transformation]
[2023-09-08 10:29:52,995: ERROR: main: No such files: 'artifacts/data_ingestion/samsum_dataset\train\dataset_info.json', nor 'artifacts/data_ingestion/samsum_dataset\train\state.json' found. Expected to load a `Dataset` object but provided path is not a `Dataset`.]
Traceback (most recent call last):
  File "c:\Users\shiva\OneDrive\Desktop\shivam\Text_Summarization\main.py", line 38, in <module>
    data_transformation.main()
  File "c:\users\shiva\onedrive\desktop\shivam\text_summarization\src\textSummarizer\pipeline\stage_03_data_transformation.py", line 14, in main
    data_transformation.convert()
  File "c:\users\shiva\onedrive\desktop\shivam\text_summarization\src\textSummarizer\conponents\data_transformation.py", line 32, in convert
    dataset_samsum = load_from_disk(self.config.data_path)
  File "C:\Users\shiva\OneDrive\Desktop\shivam\Text_Summarization\helloo\lib\site-packages\datasets\load.py", line 2250, in load_from_disk
    return DatasetDict.load_from_disk(dataset_path, keep_in_memory=keep_in_memory, storage_options=storage_options)
  File "C:\Users\shiva\OneDrive\Desktop\shivam\Text_Summarization\helloo\lib\site-packages\datasets\dataset_dict.py", line 1371, in load_from_disk
    dataset_dict[k] = Dataset.load_from_disk(
  File "C:\Users\shiva\OneDrive\Desktop\shivam\Text_Summarization\helloo\lib\site-packages\datasets\arrow_dataset.py", line 1671, in load_from_disk
    raise FileNotFoundError(
FileNotFoundError: No such files: 'artifacts/data_ingestion/samsum_dataset\train\dataset_info.json', nor 'artifacts/data_ingestion/samsum_dataset\train\state.json' found. Expected to load a `Dataset` object but provided path is not a `Dataset`.
[2023-09-08 10:32:27,479: INFO: main: >>>>>> stage Data Ingestion stage started <<<<<<]
[2023-09-08 10:32:27,481: INFO: common: yaml file: config\config.yaml loaded successfully]
[2023-09-08 10:32:27,482: INFO: common: yaml file: params.yaml loaded successfully]
[2023-09-08 10:32:27,482: INFO: common: created directory at: artifacts]
[2023-09-08 10:32:27,482: INFO: common: created directory at: artifacts/data_ingestion]
[2023-09-08 10:32:27,483: INFO: main: >>>>>> stage Data Ingestion stage completed <<<<<<

x==========x]
[2023-09-08 10:32:27,483: INFO: main: >>>>>> stage Data Validation stage started <<<<<<]
[2023-09-08 10:32:27,484: INFO: common: yaml file: config\config.yaml loaded successfully]
[2023-09-08 10:32:27,484: INFO: common: yaml file: params.yaml loaded successfully]
[2023-09-08 10:32:27,484: INFO: common: created directory at: artifacts]
[2023-09-08 10:32:27,485: INFO: common: created directory at: artifacts/data_validation]
[2023-09-08 10:32:27,486: INFO: main: >>>>>> stage Data Validation stage completed <<<<<<

x==========x]
[2023-09-08 10:32:27,486: INFO: main: >>>>>> stage Data Transformation stage started <<<<<<]
[2023-09-08 10:32:27,487: INFO: common: yaml file: config\config.yaml loaded successfully]
[2023-09-08 10:32:27,488: INFO: common: yaml file: params.yaml loaded successfully]
[2023-09-08 10:32:27,488: INFO: common: created directory at: artifacts]
[2023-09-08 10:32:27,489: INFO: common: created directory at: artifacts/data_transformation]
[2023-09-08 10:32:28,437: INFO: main: >>>>>> stage Data Transformation stage completed <<<<<<

x==========x]
[2023-09-08 10:32:28,437: INFO: main: *******************]
[2023-09-08 10:32:28,437: INFO: main: >>>>>> stage Model Trainer stage started <<<<<<]
[2023-09-08 10:32:28,440: INFO: common: yaml file: config\config.yaml loaded successfully]
[2023-09-08 10:32:28,441: INFO: common: yaml file: params.yaml loaded successfully]
[2023-09-08 10:32:28,441: INFO: common: created directory at: artifacts]
[2023-09-08 10:32:28,442: INFO: common: created directory at: artifacts/model_trainer]
[2023-09-08 10:32:34,018: ERROR: main: "Column test not in the dataset. Current columns in the dataset: ['id', 'dialogue', 'summary', 'input_ids', 'attention_mask', 'labels']"]
Traceback (most recent call last):
  File "c:\Users\shiva\OneDrive\Desktop\shivam\Text_Summarization\main.py", line 51, in <module>
    model_trainer.main()
  File "c:\users\shiva\onedrive\desktop\shivam\text_summarization\src\textSummarizer\pipeline\stage_04_model_trainer.py", line 14, in main
    model_trainer_config.train()
  File "c:\users\shiva\onedrive\desktop\shivam\text_summarization\src\textSummarizer\conponents\model_trainer.py", line 44, in train
    train_dataset=dataset_samsum_pt["test"],
  File "C:\Users\shiva\OneDrive\Desktop\shivam\Text_Summarization\helloo\lib\site-packages\datasets\arrow_dataset.py", line 2803, in __getitem__
    return self._getitem(key)
  File "C:\Users\shiva\OneDrive\Desktop\shivam\Text_Summarization\helloo\lib\site-packages\datasets\arrow_dataset.py", line 2787, in _getitem
    pa_subtable = query_table(self._data, key, indices=self._indices if self._indices is not None else None)
  File "C:\Users\shiva\OneDrive\Desktop\shivam\Text_Summarization\helloo\lib\site-packages\datasets\formatting\formatting.py", line 580, in query_table
    _check_valid_column_key(key, table.column_names)
  File "C:\Users\shiva\OneDrive\Desktop\shivam\Text_Summarization\helloo\lib\site-packages\datasets\formatting\formatting.py", line 520, in _check_valid_column_key
    raise KeyError(f"Column {key} not in the dataset. Current columns in the dataset: {columns}")
KeyError: "Column test not in the dataset. Current columns in the dataset: ['id', 'dialogue', 'summary', 'input_ids', 'attention_mask', 'labels']"
[2023-09-08 10:35:12,828: INFO: main: >>>>>> stage Data Ingestion stage started <<<<<<]
[2023-09-08 10:35:12,830: INFO: common: yaml file: config\config.yaml loaded successfully]
[2023-09-08 10:35:12,831: INFO: common: yaml file: params.yaml loaded successfully]
[2023-09-08 10:35:12,831: INFO: common: created directory at: artifacts]
[2023-09-08 10:35:12,832: INFO: common: created directory at: artifacts/data_ingestion]
[2023-09-08 10:35:12,832: INFO: main: >>>>>> stage Data Ingestion stage completed <<<<<<

x==========x]
[2023-09-08 10:35:12,832: INFO: main: >>>>>> stage Data Validation stage started <<<<<<]
[2023-09-08 10:35:12,834: INFO: common: yaml file: config\config.yaml loaded successfully]
[2023-09-08 10:35:12,834: INFO: common: yaml file: params.yaml loaded successfully]
[2023-09-08 10:35:12,835: INFO: common: created directory at: artifacts]
[2023-09-08 10:35:12,835: INFO: common: created directory at: artifacts/data_validation]
[2023-09-08 10:35:12,836: INFO: main: >>>>>> stage Data Validation stage completed <<<<<<

x==========x]
[2023-09-08 10:35:12,836: INFO: main: >>>>>> stage Data Transformation stage started <<<<<<]
[2023-09-08 10:35:12,840: INFO: common: yaml file: config\config.yaml loaded successfully]
[2023-09-08 10:35:12,841: INFO: common: yaml file: params.yaml loaded successfully]
[2023-09-08 10:35:12,841: INFO: common: created directory at: artifacts]
[2023-09-08 10:35:12,841: INFO: common: created directory at: artifacts/data_transformation]
[2023-09-08 10:35:14,789: INFO: main: >>>>>> stage Data Transformation stage completed <<<<<<

x==========x]
[2023-09-08 10:35:14,789: INFO: main: *******************]
[2023-09-08 10:35:14,790: INFO: main: >>>>>> stage Model Trainer stage started <<<<<<]
[2023-09-08 10:35:14,791: INFO: common: yaml file: config\config.yaml loaded successfully]
[2023-09-08 10:35:14,792: INFO: common: yaml file: params.yaml loaded successfully]
[2023-09-08 10:35:14,792: INFO: common: created directory at: artifacts]
[2023-09-08 10:35:14,792: INFO: common: created directory at: artifacts/model_trainer]
[2023-09-08 10:35:20,054: ERROR: main: "Column train not in the dataset. Current columns in the dataset: ['id', 'dialogue', 'summary', 'input_ids', 'attention_mask', 'labels']"]
Traceback (most recent call last):
  File "c:\Users\shiva\OneDrive\Desktop\shivam\Text_Summarization\main.py", line 51, in <module>
    model_trainer.main()
  File "c:\users\shiva\onedrive\desktop\shivam\text_summarization\src\textSummarizer\pipeline\stage_04_model_trainer.py", line 14, in main
    model_trainer_config.train()
  File "c:\users\shiva\onedrive\desktop\shivam\text_summarization\src\textSummarizer\conponents\model_trainer.py", line 44, in train
    train_dataset=dataset_samsum_pt["train"],
  File "C:\Users\shiva\OneDrive\Desktop\shivam\Text_Summarization\helloo\lib\site-packages\datasets\arrow_dataset.py", line 2803, in __getitem__
    return self._getitem(key)
  File "C:\Users\shiva\OneDrive\Desktop\shivam\Text_Summarization\helloo\lib\site-packages\datasets\arrow_dataset.py", line 2787, in _getitem
    pa_subtable = query_table(self._data, key, indices=self._indices if self._indices is not None else None)
  File "C:\Users\shiva\OneDrive\Desktop\shivam\Text_Summarization\helloo\lib\site-packages\datasets\formatting\formatting.py", line 580, in query_table
    _check_valid_column_key(key, table.column_names)
  File "C:\Users\shiva\OneDrive\Desktop\shivam\Text_Summarization\helloo\lib\site-packages\datasets\formatting\formatting.py", line 520, in _check_valid_column_key
    raise KeyError(f"Column {key} not in the dataset. Current columns in the dataset: {columns}")
KeyError: "Column train not in the dataset. Current columns in the dataset: ['id', 'dialogue', 'summary', 'input_ids', 'attention_mask', 'labels']"
[2023-09-08 10:35:47,704: INFO: main: >>>>>> stage Data Ingestion stage started <<<<<<]
[2023-09-08 10:35:47,706: INFO: common: yaml file: config\config.yaml loaded successfully]
[2023-09-08 10:35:47,707: INFO: common: yaml file: params.yaml loaded successfully]
[2023-09-08 10:35:47,707: INFO: common: created directory at: artifacts]
[2023-09-08 10:35:47,707: INFO: common: created directory at: artifacts/data_ingestion]
[2023-09-08 10:35:47,707: INFO: main: >>>>>> stage Data Ingestion stage completed <<<<<<

x==========x]
[2023-09-08 10:35:47,707: INFO: main: >>>>>> stage Data Validation stage started <<<<<<]
[2023-09-08 10:35:47,709: INFO: common: yaml file: config\config.yaml loaded successfully]
[2023-09-08 10:35:47,710: INFO: common: yaml file: params.yaml loaded successfully]
[2023-09-08 10:35:47,710: INFO: common: created directory at: artifacts]
[2023-09-08 10:35:47,710: INFO: common: created directory at: artifacts/data_validation]
[2023-09-08 10:35:47,711: INFO: main: >>>>>> stage Data Validation stage completed <<<<<<

x==========x]
[2023-09-08 10:35:47,711: INFO: main: >>>>>> stage Data Transformation stage started <<<<<<]
[2023-09-08 10:35:47,713: INFO: common: yaml file: config\config.yaml loaded successfully]
[2023-09-08 10:35:47,714: INFO: common: yaml file: params.yaml loaded successfully]
[2023-09-08 10:35:47,714: INFO: common: created directory at: artifacts]
[2023-09-08 10:35:47,714: INFO: common: created directory at: artifacts/data_transformation]
[2023-09-08 10:35:48,379: INFO: main: >>>>>> stage Data Transformation stage completed <<<<<<

x==========x]
[2023-09-08 10:35:48,379: INFO: main: *******************]
[2023-09-08 10:35:48,379: INFO: main: >>>>>> stage Model Trainer stage started <<<<<<]
[2023-09-08 10:35:48,381: INFO: common: yaml file: config\config.yaml loaded successfully]
[2023-09-08 10:35:48,382: INFO: common: yaml file: params.yaml loaded successfully]
[2023-09-08 10:35:48,382: INFO: common: created directory at: artifacts]
[2023-09-08 10:35:48,382: INFO: common: created directory at: artifacts/model_trainer]
[2023-09-08 10:35:54,016: ERROR: main: "Column train not in the dataset. Current columns in the dataset: ['id', 'dialogue', 'summary', 'input_ids', 'attention_mask', 'labels']"]
Traceback (most recent call last):
  File "c:\Users\shiva\OneDrive\Desktop\shivam\Text_Summarization\main.py", line 51, in <module>
    model_trainer.main()
  File "c:\users\shiva\onedrive\desktop\shivam\text_summarization\src\textSummarizer\pipeline\stage_04_model_trainer.py", line 14, in main
    model_trainer_config.train()
  File "c:\users\shiva\onedrive\desktop\shivam\text_summarization\src\textSummarizer\conponents\model_trainer.py", line 44, in train
    train_dataset=dataset_samsum_pt["train"],
  File "C:\Users\shiva\OneDrive\Desktop\shivam\Text_Summarization\helloo\lib\site-packages\datasets\arrow_dataset.py", line 2803, in __getitem__
    return self._getitem(key)
  File "C:\Users\shiva\OneDrive\Desktop\shivam\Text_Summarization\helloo\lib\site-packages\datasets\arrow_dataset.py", line 2787, in _getitem
    pa_subtable = query_table(self._data, key, indices=self._indices if self._indices is not None else None)
  File "C:\Users\shiva\OneDrive\Desktop\shivam\Text_Summarization\helloo\lib\site-packages\datasets\formatting\formatting.py", line 580, in query_table
    _check_valid_column_key(key, table.column_names)
  File "C:\Users\shiva\OneDrive\Desktop\shivam\Text_Summarization\helloo\lib\site-packages\datasets\formatting\formatting.py", line 520, in _check_valid_column_key
    raise KeyError(f"Column {key} not in the dataset. Current columns in the dataset: {columns}")
KeyError: "Column train not in the dataset. Current columns in the dataset: ['id', 'dialogue', 'summary', 'input_ids', 'attention_mask', 'labels']"
[2023-09-08 10:36:54,247: INFO: common: yaml file: config\config.yaml loaded successfully]
[2023-09-08 10:36:54,248: INFO: common: yaml file: params.yaml loaded successfully]
[2023-09-08 10:36:54,249: INFO: common: created directory at: artifacts]
[2023-09-08 10:36:54,250: INFO: common: created directory at: artifacts/data_ingestion]
[2023-09-08 10:37:22,093: INFO: common: yaml file: config\config.yaml loaded successfully]
[2023-09-08 10:37:22,094: INFO: common: yaml file: params.yaml loaded successfully]
[2023-09-08 10:37:22,095: INFO: common: created directory at: artifacts]
[2023-09-08 10:37:22,095: INFO: common: created directory at: artifacts/data_validation]
[2023-09-08 10:37:37,910: INFO: common: yaml file: config\config.yaml loaded successfully]
[2023-09-08 10:37:37,911: INFO: common: yaml file: params.yaml loaded successfully]
[2023-09-08 10:37:37,912: INFO: common: created directory at: artifacts]
[2023-09-08 10:37:37,913: INFO: common: created directory at: artifacts/data_ingestion]
[2023-09-08 10:38:03,208: INFO: common: yaml file: config\config.yaml loaded successfully]
[2023-09-08 10:38:03,209: INFO: common: yaml file: params.yaml loaded successfully]
[2023-09-08 10:38:03,210: INFO: common: created directory at: artifacts]
[2023-09-08 10:38:03,210: INFO: common: created directory at: artifacts/data_transformation]
[2023-09-08 10:38:24,125: INFO: common: yaml file: config\config.yaml loaded successfully]
[2023-09-08 10:38:24,127: INFO: common: yaml file: params.yaml loaded successfully]
[2023-09-08 10:38:24,127: INFO: common: created directory at: artifacts]
[2023-09-08 10:38:24,128: INFO: common: created directory at: artifacts/model_trainer]
[2023-09-08 10:39:51,883: INFO: common: yaml file: config\config.yaml loaded successfully]
[2023-09-08 10:39:51,885: INFO: common: yaml file: params.yaml loaded successfully]
[2023-09-08 10:39:51,885: INFO: common: created directory at: artifacts]
[2023-09-08 10:39:51,886: INFO: common: created directory at: artifacts/model_trainer]
[2023-09-08 10:40:38,286: INFO: common: yaml file: config\config.yaml loaded successfully]
[2023-09-08 10:40:38,287: INFO: common: yaml file: params.yaml loaded successfully]
[2023-09-08 10:40:38,287: INFO: common: created directory at: artifacts]
[2023-09-08 10:40:38,288: INFO: common: created directory at: artifacts/data_ingestion]
[2023-09-08 10:40:50,537: INFO: common: yaml file: config\config.yaml loaded successfully]
[2023-09-08 10:40:50,538: INFO: common: yaml file: params.yaml loaded successfully]
[2023-09-08 10:40:50,539: INFO: common: created directory at: artifacts]
[2023-09-08 10:40:50,539: INFO: common: created directory at: artifacts/data_validation]
[2023-09-08 10:41:29,839: INFO: common: yaml file: config\config.yaml loaded successfully]
[2023-09-08 10:41:29,840: INFO: common: yaml file: params.yaml loaded successfully]
[2023-09-08 10:41:29,841: INFO: common: created directory at: artifacts]
[2023-09-08 10:41:29,841: INFO: common: created directory at: artifacts/data_validation]
[2023-09-08 10:42:13,455: INFO: common: yaml file: config\config.yaml loaded successfully]
[2023-09-08 10:42:13,457: INFO: common: yaml file: params.yaml loaded successfully]
[2023-09-08 10:42:13,457: INFO: common: created directory at: artifacts]
[2023-09-08 10:42:13,458: INFO: common: created directory at: artifacts/data_validation]
[2023-09-08 10:44:17,816: INFO: common: yaml file: config\config.yaml loaded successfully]
[2023-09-08 10:44:17,817: INFO: common: yaml file: params.yaml loaded successfully]
[2023-09-08 10:44:17,818: INFO: common: created directory at: artifacts]
[2023-09-08 10:44:17,819: INFO: common: created directory at: artifacts/data_ingestion]
[2023-09-08 10:44:32,432: INFO: 1434958058: artifacts/data_ingestion/data.zip download! with following info: 
Connection: close
Content-Length: 7903594
Cache-Control: max-age=300
Content-Security-Policy: default-src 'none'; style-src 'unsafe-inline'; sandbox
Content-Type: application/zip
ETag: "dbc016a060da18070593b83afff580c9b300f0b6ea4147a7988433e04df246ca"
Strict-Transport-Security: max-age=31536000
X-Content-Type-Options: nosniff
X-Frame-Options: deny
X-XSS-Protection: 1; mode=block
X-GitHub-Request-Id: E596:1820C0:17C326:2256DC:64FAAD7B
Accept-Ranges: bytes
Date: Fri, 08 Sep 2023 05:13:44 GMT
Via: 1.1 varnish
X-Served-By: cache-del21721-DEL
X-Cache: MISS
X-Cache-Hits: 0
X-Timer: S1694150011.223279,VS0,VE13452
Vary: Authorization,Accept-Encoding,Origin
Access-Control-Allow-Origin: *
Cross-Origin-Resource-Policy: cross-origin
X-Fastly-Request-ID: 35159a50d64f3961f24701e430c6778874fc6d0f
Expires: Fri, 08 Sep 2023 05:18:44 GMT
Source-Age: 11

]
[2023-09-08 10:44:55,256: INFO: common: yaml file: config\config.yaml loaded successfully]
[2023-09-08 10:44:55,257: INFO: common: yaml file: params.yaml loaded successfully]
[2023-09-08 10:44:55,258: INFO: common: created directory at: artifacts]
[2023-09-08 10:44:55,258: INFO: common: created directory at: artifacts/data_validation]
[2023-09-08 10:45:10,521: INFO: common: yaml file: config\config.yaml loaded successfully]
[2023-09-08 10:45:10,522: INFO: common: yaml file: params.yaml loaded successfully]
[2023-09-08 10:45:10,522: INFO: common: created directory at: artifacts]
[2023-09-08 10:45:10,523: INFO: common: created directory at: artifacts/data_transformation]
[2023-09-08 10:45:34,308: INFO: common: yaml file: config\config.yaml loaded successfully]
[2023-09-08 10:45:34,310: INFO: common: yaml file: params.yaml loaded successfully]
[2023-09-08 10:45:34,310: INFO: common: created directory at: artifacts]
[2023-09-08 10:45:34,311: INFO: common: created directory at: artifacts/model_trainer]
[2023-09-08 10:46:07,543: INFO: main: >>>>>> stage Data Ingestion stage started <<<<<<]
[2023-09-08 10:46:07,544: INFO: common: yaml file: config\config.yaml loaded successfully]
[2023-09-08 10:46:07,545: INFO: common: yaml file: params.yaml loaded successfully]
[2023-09-08 10:46:07,545: INFO: common: created directory at: artifacts]
[2023-09-08 10:46:07,545: INFO: common: created directory at: artifacts/data_ingestion]
[2023-09-08 10:46:07,545: INFO: main: >>>>>> stage Data Ingestion stage completed <<<<<<

x==========x]
[2023-09-08 10:46:07,546: INFO: main: >>>>>> stage Data Validation stage started <<<<<<]
[2023-09-08 10:46:07,547: INFO: common: yaml file: config\config.yaml loaded successfully]
[2023-09-08 10:46:07,548: INFO: common: yaml file: params.yaml loaded successfully]
[2023-09-08 10:46:07,548: INFO: common: created directory at: artifacts]
[2023-09-08 10:46:07,548: INFO: common: created directory at: artifacts/data_validation]
[2023-09-08 10:46:07,549: INFO: main: >>>>>> stage Data Validation stage completed <<<<<<

x==========x]
[2023-09-08 10:46:07,549: INFO: main: >>>>>> stage Data Transformation stage started <<<<<<]
[2023-09-08 10:46:07,551: INFO: common: yaml file: config\config.yaml loaded successfully]
[2023-09-08 10:46:07,552: INFO: common: yaml file: params.yaml loaded successfully]
[2023-09-08 10:46:07,552: INFO: common: created directory at: artifacts]
[2023-09-08 10:46:07,553: INFO: common: created directory at: artifacts/data_transformation]
[2023-09-08 10:46:09,339: ERROR: main: [Errno 22] Invalid argument: 'C:/Users/shiva/OneDrive/Desktop/shivam/Text_Summarization/artifacts/data_transformation/samsum_dataset/train/data-00000-of-00001.arrow']
Traceback (most recent call last):
  File "c:\Users\shiva\OneDrive\Desktop\shivam\Text_Summarization\main.py", line 38, in <module>
    data_transformation.main()
  File "c:\users\shiva\onedrive\desktop\shivam\text_summarization\src\textSummarizer\pipeline\stage_03_data_transformation.py", line 14, in main
    data_transformation.convert()
  File "c:\users\shiva\onedrive\desktop\shivam\text_summarization\src\textSummarizer\conponents\data_transformation.py", line 33, in convert
    dataset_samsum_pt.save_to_disk(os.path.join(self.config.root_dir,"samsum_dataset"))
  File "C:\Users\shiva\OneDrive\Desktop\shivam\Text_Summarization\helloo\lib\site-packages\datasets\dataset_dict.py", line 1279, in save_to_disk
    dataset.save_to_disk(
  File "C:\Users\shiva\OneDrive\Desktop\shivam\Text_Summarization\helloo\lib\site-packages\datasets\arrow_dataset.py", line 1533, in save_to_disk
    for job_id, done, content in Dataset._save_to_disk_single(**kwargs):
  File "C:\Users\shiva\OneDrive\Desktop\shivam\Text_Summarization\helloo\lib\site-packages\datasets\arrow_dataset.py", line 1555, in _save_to_disk_single
    writer = ArrowWriter(
  File "C:\Users\shiva\OneDrive\Desktop\shivam\Text_Summarization\helloo\lib\site-packages\datasets\arrow_writer.py", line 334, in __init__
    self.stream = self._fs.open(fs_token_paths[2][0], "wb")
  File "C:\Users\shiva\OneDrive\Desktop\shivam\Text_Summarization\helloo\lib\site-packages\fsspec\spec.py", line 1241, in open
    f = self._open(
  File "C:\Users\shiva\OneDrive\Desktop\shivam\Text_Summarization\helloo\lib\site-packages\fsspec\implementations\local.py", line 184, in _open
    return LocalFileOpener(path, mode, fs=self, **kwargs)
  File "C:\Users\shiva\OneDrive\Desktop\shivam\Text_Summarization\helloo\lib\site-packages\fsspec\implementations\local.py", line 315, in __init__
    self._open()
  File "C:\Users\shiva\OneDrive\Desktop\shivam\Text_Summarization\helloo\lib\site-packages\fsspec\implementations\local.py", line 320, in _open
    self.f = open(self.path, mode=self.mode)
OSError: [Errno 22] Invalid argument: 'C:/Users/shiva/OneDrive/Desktop/shivam/Text_Summarization/artifacts/data_transformation/samsum_dataset/train/data-00000-of-00001.arrow'
[2023-09-08 10:47:46,079: INFO: main: >>>>>> stage Data Ingestion stage started <<<<<<]
[2023-09-08 10:47:46,081: INFO: common: yaml file: config\config.yaml loaded successfully]
[2023-09-08 10:47:46,082: INFO: common: yaml file: params.yaml loaded successfully]
[2023-09-08 10:47:46,082: INFO: common: created directory at: artifacts]
[2023-09-08 10:47:46,082: INFO: common: created directory at: artifacts/data_ingestion]
[2023-09-08 10:47:46,083: INFO: main: >>>>>> stage Data Ingestion stage completed <<<<<<

x==========x]
[2023-09-08 10:47:46,083: INFO: main: >>>>>> stage Data Validation stage started <<<<<<]
[2023-09-08 10:47:46,085: INFO: common: yaml file: config\config.yaml loaded successfully]
[2023-09-08 10:47:46,086: INFO: common: yaml file: params.yaml loaded successfully]
[2023-09-08 10:47:46,086: INFO: common: created directory at: artifacts]
[2023-09-08 10:47:46,087: INFO: common: created directory at: artifacts/data_validation]
[2023-09-08 10:47:46,089: INFO: main: >>>>>> stage Data Validation stage completed <<<<<<

x==========x]
[2023-09-08 10:47:46,089: INFO: main: >>>>>> stage Data Transformation stage started <<<<<<]
[2023-09-08 10:47:46,091: INFO: common: yaml file: config\config.yaml loaded successfully]
[2023-09-08 10:47:46,091: INFO: common: yaml file: params.yaml loaded successfully]
[2023-09-08 10:47:46,092: INFO: common: created directory at: artifacts]
[2023-09-08 10:47:46,092: INFO: common: created directory at: artifacts/data_transformation]
[2023-09-08 10:47:47,158: INFO: main: >>>>>> stage Data Transformation stage completed <<<<<<

x==========x]
[2023-09-08 10:47:47,158: INFO: main: *******************]
[2023-09-08 10:47:47,159: INFO: main: >>>>>> stage Model Trainer stage started <<<<<<]
[2023-09-08 10:47:47,160: INFO: common: yaml file: config\config.yaml loaded successfully]
[2023-09-08 10:47:47,161: INFO: common: yaml file: params.yaml loaded successfully]
[2023-09-08 10:47:47,161: INFO: common: created directory at: artifacts]
[2023-09-08 10:47:47,161: INFO: common: created directory at: artifacts/model_trainer]
[2023-09-08 10:49:43,012: INFO: server: Started server process [30836]]
[2023-09-08 10:49:43,013: INFO: on: Waiting for application startup.]
[2023-09-08 10:49:43,013: INFO: on: Application startup complete.]
[2023-09-08 10:49:43,013: INFO: server: Uvicorn running on http://0.0.0.0:8080 (Press CTRL+C to quit)]
[2023-09-08 10:50:03,377: INFO: main: >>>>>> stage Data Ingestion stage started <<<<<<]
[2023-09-08 10:50:03,379: INFO: common: yaml file: config\config.yaml loaded successfully]
[2023-09-08 10:50:03,379: INFO: common: yaml file: params.yaml loaded successfully]
[2023-09-08 10:50:03,379: INFO: common: created directory at: artifacts]
[2023-09-08 10:50:03,380: INFO: common: created directory at: artifacts/data_ingestion]
[2023-09-08 10:50:03,380: INFO: main: >>>>>> stage Data Ingestion stage completed <<<<<<

x==========x]
[2023-09-08 10:50:03,380: INFO: main: >>>>>> stage Data Validation stage started <<<<<<]
[2023-09-08 10:50:03,381: INFO: common: yaml file: config\config.yaml loaded successfully]
[2023-09-08 10:50:03,382: INFO: common: yaml file: params.yaml loaded successfully]
[2023-09-08 10:50:03,382: INFO: common: created directory at: artifacts]
[2023-09-08 10:50:03,382: INFO: common: created directory at: artifacts/data_validation]
[2023-09-08 10:50:03,383: INFO: main: >>>>>> stage Data Validation stage completed <<<<<<

x==========x]
[2023-09-08 10:50:03,383: INFO: main: >>>>>> stage Data Transformation stage started <<<<<<]
[2023-09-08 10:50:03,385: INFO: common: yaml file: config\config.yaml loaded successfully]
[2023-09-08 10:50:03,386: INFO: common: yaml file: params.yaml loaded successfully]
[2023-09-08 10:50:03,386: INFO: common: created directory at: artifacts]
[2023-09-08 10:50:03,386: INFO: common: created directory at: artifacts/data_transformation]
[2023-09-08 10:50:04,460: INFO: main: >>>>>> stage Data Transformation stage completed <<<<<<

x==========x]
[2023-09-08 10:50:04,460: INFO: main: *******************]
[2023-09-08 10:50:04,460: INFO: main: >>>>>> stage Model Trainer stage started <<<<<<]
[2023-09-08 10:50:04,462: INFO: common: yaml file: config\config.yaml loaded successfully]
[2023-09-08 10:50:04,463: INFO: common: yaml file: params.yaml loaded successfully]
[2023-09-08 10:50:04,463: INFO: common: created directory at: artifacts]
[2023-09-08 10:50:04,464: INFO: common: created directory at: artifacts/model_trainer]
[2023-09-08 10:50:31,445: INFO: server: Shutting down]
[2023-09-08 10:50:31,553: INFO: on: Waiting for application shutdown.]
[2023-09-08 10:50:31,554: INFO: on: Application shutdown complete.]
[2023-09-08 10:50:31,554: INFO: server: Finished server process [30836]]
